Workbook

Sheet 📋 사용 안내
A1: HACCP 원료수불부 & 원가관리 통합 시스템
A2: (주)단지 | 품목제조보고 기반 80개 제품 · 167개 원재료 자동화 관리
B4: 📌 시트 구성
B5: 시트명 | C5: 용도 | D5: 설명
B6: 🏭 원료 마스터 | C6: 단가 관리 | D6: 원료별 단가(원/kg) 입력 → 전 시트 자동 반영
B7: 📦 일일 생산 입력 | C7: 생산 실적 입력 | D7: 날짜·제품·생산량 입력 → 원료 사용량·원가 자동 계산
B8: 📊 월별 원료수불부 | C8: 재고 관리 | D8: 원료별 전재고/입고/사용/잔고 자동 집계
B9: 💰 원가 분석 | C9: 원가율 산출 | D9: 제품별 kg당 원재료비 & 원가율 자동 계산
B10: 🔖 배합비 참조 | C10: 숨김 시트 | D10: 수식 연산용 배합비 테이블 (수정 불필요)
B12: 📝 사용 순서
B13: STEP 1 | C13: 단가 입력 | D13: 🏭 원료 마스터 → 노란칸에 원료별 단가(원/kg) 입력
B14: STEP 2 | C14: 초기 재고 | D14: 📊 월별 원료수불부 → 전월재고(노란칸) 입력
B15: STEP 3 | C15: 입고 기록 | D15: 📊 월별 원료수불부 → 날짜별 입고 열에 입고량 입력
B16: STEP 4 | C16: 생산 입력 | D16: 📦 일일 생산 입력 → 날짜·제품명·생산량(kg) 입력
B17: STEP 5 | C17: 결과 확인 | D17: 원료 사용량·잔고·원가율이 자동 계산됨
B19: ⚠️ 주의 사항
B20: 단위 | D20: 생산량 및 재고는 모두 kg 기준
B21: 제품명 입력 | D21: 📦 일일 생산 입력의 제품명은 🔖 배합비 참조 시트 B1행 이름과 정확히 일치해야 함
B22: 배합비없음 | D22: 호박영양찰떡(1개)은 배합비 미등록으로 원료 계산 제외

Sheet 🏭 원료 마스터
A1: 원료 마스터 (단가 관리)
A2: ⚡ 노란색 칸(단가/규격)을 입력하면 원가 분석 시트에 자동 반영됩니다.
A3: No | B3: 원 료 명 | C3: 단가(원/kg) | D3: 규격/단위 | E3: 주요 거래처 | F3: 비고 | G3: 사용 제품 수
A4: 1 | B4: 간장 | C4: =IFERROR(SUMPRODUCT(('📥 원재료 입고'!$B$4:$B$500="간장")*'📥 원재료 입고'!$E$4:$E$500*'📥 원재료 입고'!$F$4:$F$500)/SUMPRODUCT(('📥 원재료 입고'!$B$4:$B$500="간장")*'📥 원재료 입고'!$E$4:$E$500),0) -> 0 | D4: kg | G4: 1
A5: 2 | B5: 강낭콩((울타리콩)) | C5: =IFERROR(SUMPRODUCT(('📥 원재료 입고'!$B$4:$B$500="강낭콩((울타리콩))")*'📥 원재료 입고'!$E$4:$E$500*'📥 원재료 입고'!$F$4:$F$500)/SUMPRODUCT(('📥 원재료 입고'!$B$4:$B$500="강낭콩((울타리콩))")*'📥 원재료 입고'!$E$4:$E$500),0) -> 0 | D5: kg | G5: 5
A6: 3 | B6: 건조딸기다이스(외국산) | C6: =IFERROR(SUMPRODUCT(('📥 원재료 입고'!$B$4:$B$500="건조딸기다이스(외국산)")*'📥 원재료 입고'!$E$4:$E$500*'📥 원재료 입고'!$F$4:$F$500)/SUMPRODUCT(('📥 원재료 입고'!$B$4:$B$500="건조딸기다이스(외국산)")*'📥 원재료 입고'!$E$4:$E$500),0) -> 0 | D6: kg | G6: 1
A7: 4 | B7: 건포도 | C7: =IFERROR(SUMPRODUCT(('📥 원재료 입고'!$B$4:$B$500="건포도")*'📥 원재료 입고'!$E$4:$E$500*'📥 원재료 입고'!$F$4:$F$500)/SUMPRODUCT(('📥 원재료 입고'!$B$4:$B$500="건포도")*'📥 원재료 입고'!$E$4:$E$500),0) -> 0 | D7: kg | G7: 2
A8: 5 | B8: 건호박채(중국산) | C8: =IFERROR(SUMPRODUCT(('📥 원재료 입고'!$B$4:$B$500="건호박채(중국산)")*'📥 원재료 입고'!$E$4:$E$500*'📥 원재료 입고'!$F$4:$F$500)/SUMPRODUCT(('📥 원재료 입고'!$B$4:$B$500="건호박채(중국산)")*'📥 원재료 입고'!$E$4:$E$500),0) -> 0 | D8: kg | G8: 11
A9: 6 | B9: 검정깨(흑임자) | C9: =IFERROR(SUMPRODUCT(('📥 원재료 입고'!$B$4:$B$500="검정깨(흑임자)")*'📥 원재료 입고'!$E$4:$E$500*'📥 원재료 입고'!$F$4:$F$500)/SUMPRODUCT(('📥 원재료 입고'!$B$4:$B$500="검정깨(흑임자)")*'📥 원재료 입고'!$E$4:$E$500),0) -> 0 | D9: kg | G9: 5
A10: 7 | B10: 검정콩 | C10: =IFERROR(SUMPRODUCT(('📥 원재료 입고'!$B$4:$B$500="검정콩")*'📥 원재료 입고'!$E$4:$E$500*'📥 원재료 입고'!$F$4:$F$500)/SUMPRODUCT(('📥 원재료 입고'!$B$4:$B$500="검정콩")*'📥 원재료 입고'!$E$4:$E$500),0) -> 0 | D10: kg | G10: 6
A11: 8 | B11: 계피가루 | C11: =IFERROR(SUMPRODUCT(('📥 원재료 입고'!$B$4:$B$500="계피가루")*'📥 원재료 입고'!$E$4:$E$500*'📥 원재료 입고'!$F$4:$F$500)/SUMPRODUCT(('📥 원재료 입고'!$B$4:$B$500="계피가루")*'📥 원재료 입고'!$E$4:$E$500),0) -> 0 | D11: kg | G11: 1
A12: 9 | B12: 고구마가루 | C12: =IFERROR(SUMPRODUCT(('📥 원재료 입고'!$B$4:$B$500="고구마가루")*'📥 원재료 입고'!$E$4:$E$500*'📥 원재료 입고'!$F$4:$F$500)/SUMPRODUCT(('📥 원재료 입고'!$B$4:$B$500="고구마가루")*'📥 원재료 입고'!$E$4:$E$500),0) -> 0 | D12: kg
A13: 10 | B13: 고구마무스 | C13: =IFERROR(SUMPRODUCT(('📥 원재료 입고'!$B$4:$B$500="고구마무스")*'📥 원재료 입고'!$E$4:$E$500*'📥 원재료 입고'!$F$4:$F$500)/SUMPRODUCT(('📥 원재료 입고'!$B$4:$B$500="고구마무스")*'📥 원재료 입고'!$E$4:$E$500),0) -> 0 | D13: kg | G13: 1
A14: 11 | B14: 고려엉겅퀴((곤드레)국내산) | C14: =IFERROR(SUMPRODUCT(('📥 원재료 입고'!$B$4:$B$500="고려엉겅퀴((곤드레)국내산)")*'📥 원재료 입고'!$E$4:$E$500*'📥 원재료 입고'!$F$4:$F$500)/SUMPRODUCT(('📥 원재료 입고'!$B$4:$B$500="고려엉겅퀴((곤드레)국내산)")*'📥 원재료 입고'!$E$4:$E$500),0) -> 0 | D14: kg | G14: 1
A15: 12 | B15: 기타가공품(복분자가루) | C15: =IFERROR(SUMPRODUCT(('📥 원재료 입고'!$B$4:$B$500="기타가공품(복분자가루)")*'📥 원재료 입고'!$E$4:$E$500*'📥 원재료 입고'!$F$4:$F$500)/SUMPRODUCT(('📥 원재료 입고'!$B$4:$B$500="기타가공품(복분자가루)")*'📥 원재료 입고'!$E$4:$E$500),0) -> 0 | D15: kg | G15: 1
A16: 13 | B16: 기타가공품(슈퍼소프트엠) | C16: =IFERROR(SUMPRODUCT(('📥 원재료 입고'!$B$4:$B$500="기타가공품(슈퍼소프트엠)")*'📥 원재료 입고'!$E$4:$E$500*'📥 원재료 입고'!$F$4:$F$500)/SUMPRODUCT(('📥 원재료 입고'!$B$4:$B$500="기타가공품(슈퍼소프트엠)")*'📥 원재료 입고'!$E$4:$E$500),0) -> 0 | D16: kg | G16: 1
A17: 14 | B17: 기타가공품(파인소프트 E-티) | C17: =IFERROR(SUMPRODUCT(('📥 원재료 입고'!$B$4:$B$500="기타가공품(파인소프트 E-티)")*'📥 원재료 입고'!$E$4:$E$500*'📥 원재료 입고'!$F$4:$F$500)/SUMPRODUCT(('📥 원재료 입고'!$B$4:$B$500="기타가공품(파인소프트 E-티)")*'📥 원재료 입고'!$E$4:$E$500),0) -> 0 | D17: kg | G17: 2
A18: 15 | B18: 기타가공품(프리미엄카스테라가루) | C18: =IFERROR(SUMPRODUCT(('📥 원재료 입고'!$B$4:$B$500="기타가공품(프리미엄카스테라가루)")*'📥 원재료 입고'!$E$4:$E$500*'📥 원재료 입고'!$F$4:$F$500)/SUMPRODUCT(('📥 원재료 입고'!$B$4:$B$500="기타가공품(프리미엄카스테라가루)")*'📥 원재료 입고'!$E$4:$E$500),0) -> 0 | D18: kg | G18: 14
A19: 16 | B19: 기타가공품(흑임자가루) | C19: =IFERROR(SUMPRODUCT(('📥 원재료 입고'!$B$4:$B$500="기타가공품(흑임자가루)")*'📥 원재료 입고'!$E$4:$E$500*'📥 원재료 입고'!$F$4:$F$500)/SUMPRODUCT(('📥 원재료 입고'!$B$4:$B$500="기타가공품(흑임자가루)")*'📥 원재료 입고'!$E$4:$E$500),0) -> 0 | D19: kg | G19: 4
A20: 17 | B20: 기타설탕(흑설탕) | C20: =IFERROR(SUMPRODUCT(('📥 원재료 입고'!$B$4:$B$500="기타설탕(흑설탕)")*'📥 원재료 입고'!$E$4:$E$500*'📥 원재료 입고'!$F$4:$F$500)/SUMPRODUCT(('📥 원재료 입고'!$B$4:$B$500="기타설탕(흑설탕)")*'📥 원재료 입고'!$E$4:$E$500),0) -> 0 | D20: kg | G20: 5
A21: 18 | B21: 냉동쑥(국내산) | C21: =IFERROR(SUMPRODUCT(('📥 원재료 입고'!$B$4:$B$500="냉동쑥(국내산)")*'📥 원재료 입고'!$E$4:$E$500*'📥 원재료 입고'!$F$4:$F$500)/SUMPRODUCT(('📥 원재료 입고'!$B$4:$B$500="냉동쑥(국내산)")*'📥 원재료 입고'!$E$4:$E$500),0) -> 0 | D21: kg | G21: 18
A22: 19 | B22: 냉동증숙고구마(중국산) | C22: =IFERROR(SUMPRODUCT(('📥 원재료 입고'!$B$4:$B$500="냉동증숙고구마(중국산)")*'📥 원재료 입고'!$E$4:$E$500*'📥 원재료 입고'!$F$4:$F$500)/SUMPRODUCT(('📥 원재료 입고'!$B$4:$B$500="냉동증숙고구마(중국산)")*'📥 원재료 입고'!$E$4:$E$500),0) -> 0 | D22: kg | G22: 1
A23: 20 | B23: 녹차가루 | C23: =IFERROR(SUMPRODUCT(('📥 원재료 입고'!$B$4:$B$500="녹차가루")*'📥 원재료 입고'!$E$4:$E$500*'📥 원재료 입고'!$F$4:$F$500)/SUMPRODUCT(('📥 원재료 입고'!$B$4:$B$500="녹차가루")*'📥 원재료 입고'!$E$4:$E$500),0) -> 0 | D23: kg | G23: 1
A24: 21 | B24: 다크초콜릿 컴파운드칩 | C24: =IFERROR(SUMPRODUCT(('📥 원재료 입고'!$B$4:$B$500="다크초콜릿 컴파운드칩")*'📥 원재료 입고'!$E$4:$E$500*'📥 원재료 입고'!$F$4:$F$500)/SUMPRODUCT(('📥 원재료 입고'!$B$4:$B$500="다크초콜릿 컴파운드칩")*'📥 원재료 입고'!$E$4:$E$500),0) -> 0 | D24: kg | G24: 1
A25: 22 | B25: 단호박분말(중국산) | C25: =IFERROR(SUMPRODUCT(('📥 원재료 입고'!$B$4:$B$500="단호박분말(중국산)")*'📥 원재료 입고'!$E$4:$E$500*'📥 원재료 입고'!$F$4:$F$500)/SUMPRODUCT(('📥 원재료 입고'!$B$4:$B$500="단호박분말(중국산)")*'📥 원재료 입고'!$E$4:$E$500),0) -> 0 | D25: kg | G25: 19
A26: 23 | B26: 당류가공품(단호박농축액) | C26: =IFERROR(SUMPRODUCT(('📥 원재료 입고'!$B$4:$B$500="당류가공품(단호박농축액)")*'📥 원재료 입고'!$E$4:$E$500*'📥 원재료 입고'!$F$4:$F$500)/SUMPRODUCT(('📥 원재료 입고'!$B$4:$B$500="당류가공품(단호박농축액)")*'📥 원재료 입고'!$E$4:$E$500),0) -> 0 | D26: kg | G26: 9
A27: 24 | B27: 당류가공품(알룰로스,에리스리톨,스테비올배당체혼합) | C27: =IFERROR(SUMPRODUCT(('📥 원재료 입고'!$B$4:$B$500="당류가공품(알룰로스,에리스리톨,스테비올배당체혼합)")*'📥 원재료 입고'!$E$4:$E$500*'📥 원재료 입고'!$F$4:$F$500)/SUMPRODUCT(('📥 원재료 입고'!$B$4:$B$500="당류가공품(알룰로스,에리스리톨,스테비올배당체혼합)")*'📥 원재료 입고'!$E$4:$E$500),0) -> 0 | D27: kg | G27: 1
A28: 25 | B28: 당류가공품(알룰로스제로파우더) | C28: =IFERROR(SUMPRODUCT(('📥 원재료 입고'!$B$4:$B$500="당류가공품(알룰로스제로파우더)")*'📥 원재료 입고'!$E$4:$E$500*'📥 원재료 입고'!$F$4:$F$500)/SUMPRODUCT(('📥 원재료 입고'!$B$4:$B$500="당류가공품(알룰로스제로파우더)")*'📥 원재료 입고'!$E$4:$E$500),0) -> 0 | D28: kg | G28: 1
A29: 26 | B29: 당절임(완두배기) | C29: =IFERROR(SUMPRODUCT(('📥 원재료 입고'!$B$4:$B$500="당절임(완두배기)")*'📥 원재료 입고'!$E$4:$E$500*'📥 원재료 입고'!$F$4:$F$500)/SUMPRODUCT(('📥 원재료 입고'!$B$4:$B$500="당절임(완두배기)")*'📥 원재료 입고'!$E$4:$E$500),0) -> 0 | D29: kg | G29: 1
A30: 27 | B30: 대추농축액 | C30: =IFERROR(SUMPRODUCT(('📥 원재료 입고'!$B$4:$B$500="대추농축액")*'📥 원재료 입고'!$E$4:$E$500*'📥 원재료 입고'!$F$4:$F$500)/SUMPRODUCT(('📥 원재료 입고'!$B$4:$B$500="대추농축액")*'📥 원재료 입고'!$E$4:$E$500),0) -> 0 | D30: kg | G30: 1
A31: 28 | B31: 대추채(국내산) | C31: =IFERROR(SUMPRODUCT(('📥 원재료 입고'!$B$4:$B$500="대추채(국내산)")*'📥 원재료 입고'!$E$4:$E$500*'📥 원재료 입고'!$F$4:$F$500)/SUMPRODUCT(('📥 원재료 입고'!$B$4:$B$500="대추채(국내산)")*'📥 원재료 입고'!$E$4:$E$500),0) -> 0 | D31: kg | G31: 3
A32: 29 | B32: 동부(미얀마산) | C32: =IFERROR(SUMPRODUCT(('📥 원재료 입고'!$B$4:$B$500="동부(미얀마산)")*'📥 원재료 입고'!$E$4:$E$500*'📥 원재료 입고'!$F$4:$F$500)/SUMPRODUCT(('📥 원재료 입고'!$B$4:$B$500="동부(미얀마산)")*'📥 원재료 입고'!$E$4:$E$500),0) -> 0 | D32: kg | G32: 5
A33: 30 | B33: 두류가공품(백옥앙금) | C33: =IFERROR(SUMPRODUCT(('📥 원재료 입고'!$B$4:$B$500="두류가공품(백옥앙금)")*'📥 원재료 입고'!$E$4:$E$500*'📥 원재료 입고'!$F$4:$F$500)/SUMPRODUCT(('📥 원재료 입고'!$B$4:$B$500="두류가공품(백옥앙금)")*'📥 원재료 입고'!$E$4:$E$500),0) -> 0 | D33: kg | G33: 3
A34: 31 | B34: 두류가공품(콩고물) | C34: =IFERROR(SUMPRODUCT(('📥 원재료 입고'!$B$4:$B$500="두류가공품(콩고물)")*'📥 원재료 입고'!$E$4:$E$500*'📥 원재료 입고'!$F$4:$F$500)/SUMPRODUCT(('📥 원재료 입고'!$B$4:$B$500="두류가공품(콩고물)")*'📥 원재료 입고'!$E$4:$E$500),0) -> 0 | D34: kg | G34: 16
A35: 32 | B35: 두류가공품(통팥고물) | C35: =IFERROR(SUMPRODUCT(('📥 원재료 입고'!$B$4:$B$500="두류가공품(통팥고물)")*'📥 원재료 입고'!$E$4:$E$500*'📥 원재료 입고'!$F$4:$F$500)/SUMPRODUCT(('📥 원재료 입고'!$B$4:$B$500="두류가공품(통팥고물)")*'📥 원재료 입고'!$E$4:$E$500),0) -> 0 | D35: kg | G35: 3
A36: 33 | B36: 딸기레진 | C36: =IFERROR(SUMPRODUCT(('📥 원재료 입고'!$B$4:$B$500="딸기레진")*'📥 원재료 입고'!$E$4:$E$500*'📥 원재료 입고'!$F$4:$F$500)/SUMPRODUCT(('📥 원재료 입고'!$B$4:$B$500="딸기레진")*'📥 원재료 입고'!$E$4:$E$500),0) -> 0 | D36: kg | G36: 2
A37: 34 | B37: 딸기분말(스트로우베리에이드(분말)) | C37: =IFERROR(SUMPRODUCT(('📥 원재료 입고'!$B$4:$B$500="딸기분말(스트로우베리에이드(분말))")*'📥 원재료 입고'!$E$4:$E$500*'📥 원재료 입고'!$F$4:$F$500)/SUMPRODUCT(('📥 원재료 입고'!$B$4:$B$500="딸기분말(스트로우베리에이드(분말))")*'📥 원재료 입고'!$E$4:$E$500),0) -> 0 | D37: kg | G37: 1
A38: 35 | B38: 마스카포네치즈 | C38: =IFERROR(SUMPRODUCT(('📥 원재료 입고'!$B$4:$B$500="마스카포네치즈")*'📥 원재료 입고'!$E$4:$E$500*'📥 원재료 입고'!$F$4:$F$500)/SUMPRODUCT(('📥 원재료 입고'!$B$4:$B$500="마스카포네치즈")*'📥 원재료 입고'!$E$4:$E$500),0) -> 0 | D38: kg | G38: 1
A39: 36 | B39: 마카다미아분태(호주산) | C39: =IFERROR(SUMPRODUCT(('📥 원재료 입고'!$B$4:$B$500="마카다미아분태(호주산)")*'📥 원재료 입고'!$E$4:$E$500*'📥 원재료 입고'!$F$4:$F$500)/SUMPRODUCT(('📥 원재료 입고'!$B$4:$B$500="마카다미아분태(호주산)")*'📥 원재료 입고'!$E$4:$E$500),0) -> 0 | D39: kg | G39: 4
A40: 37 | B40: 멥쌀(국내산) | C40: 1050 | D40: kg | G40: 29
...

Sheet 🔖 배합비 참조
A1: 원재료명 | B1: 3종호두찹쌀떡 | C1: 곤드레약식 | D1: 꿀설기 | E1: 다이스인절미 | F1: 단호박설기 | G1: 단호박약식 | H1: 대추고약식 | I1: 딸기설기 | J1: 롤크림떡(고구마) | K1: 롤크림떡(딸기) | L1: 롤크림떡(말차) | M1: 롤크림떡(초코) | N1: 롤크림떡(치즈) | O1: 롤크림떡(흑임자) | P1: 마카다미아 왕찹쌀떡 | Q1: 마카다미아단호박왕찹쌀떡 | R1: 마카다미아복분자왕찹쌀떡 | S1: 마카다미아쑥왕찹쌀떡 | T1: 모듬설기 | U1: 모듬찰떡 | V1: 모시개떡 | W1: 모시인절미 | X1: 못난이인절미 | Y1: 무지개설기 | Z1: 밥알쑥인절미 | AA1: 손모시송편 | AB1: 송편(백) | AC1: 쇠머리떡 | AD1: 습식 멥쌀가루 | AE1: 습식 멥쌀가루(무염) | AF1: 습식 멥쌀가루(쑥) | AG1: 습식 멥쌀가루(호박) | AH1: 쑥 꿀설기 | AI1: 쑥개떡 | AJ1: 쑥버무리 | AK1: 쑥송편 | AL1: 쑥영양찰떡 | AM1: 쑥인절미 | AN1: 쑥판인절미 | AO1: 영양찰떡 | AP1: 오색송편 | AQ1: 완두배기팥시루찰떡 | AR1: 왕찹쌀떡 | AS1: 우유설기 | AT1: 인절미 | AU1: 자색고구마설기 | AV1: 자색고구마송편 | AW1: 제로슈가 우유설기 | AX1: 제로슈가 현미설기 | AY1: 제로슈거 영양찰떡 | AZ1: 찹쌀떡 | BA1: 초코설기 | BB1: 치즈설기 | BC1: 카스테라 호박인절미 | BD1: 카스테라설기 | BE1: 카스테라쑥인절미 | BF1: 카스테라왕찹쌀떡(백) | BG1: 카스테라왕찹쌀떡(쑥) | BH1: 카스테라왕찹쌀떡(호박) | BI1: 카스테라인절미 | BJ1: 카스테라호박앙금인절미 | BK1: 콩가루 쑥앙금인절미 | BL1: 콩가루 앙금인절미 | BM1: 콩고물쑥떡 | BN1: 콩고물쑥떡(동부) | BO1: 판인절미 | BP1: 한입빙수 인절미 | BQ1: 현미설기 | BR1: 호두찹쌀떡 | BS1: 호두찹쌀떡(쑥) | BT1: 호두찹쌀떡(호박) | BU1: 호박 꿀설기 | BV1: 호박 팥시루찰떡(냉동) | BW1: 호박고지 찰시루 | BX1: 호박설기 | BY1: 호박송편 | BZ1: 호박인절미 | CA1: 흑미송편 | CB1: 흑임자설기 | CC1: 흑임자약식 | CD1: 카스테라앙금인절미 | CE1: 카스테라쑥앙금인절미
A2: 간장 | B2: 0 | C2: 0 | D2: 0 | E2: 0 | F2: 0 | G2: 0 | H2: 1.6 | I2: 0 | J2: 0 | K2: 0 | L2: 0 | M2: 0 | N2: 0 | O2: 0 | P2: 0 | Q2: 0 | R2: 0 | S2: 0 | T2: 0 | U2: 0 | V2: 0 | W2: 0 | X2: 0 | Y2: 0 | Z2: 0 | AA2: 0 | AB2: 0 | AC2: 0 | AD2: 0 | AE2: 0 | AF2: 0 | AG2: 0 | AH2: 0 | AI2: 0 | AJ2: 0 | AK2: 0 | AL2: 0 | AM2: 0 | AN2: 0 | AO2: 0 | AP2: 0 | AQ2: 0 | AR2: 0 | AS2: 0 | AT2: 0 | AU2: 0 | AV2: 0 | AW2: 0 | AX2: 0 | AY2: 0 | BA2: 0 | BB2: 0 | BC2: 0 | BD2: 0 | BE2: 0 | BF2: 0 | BG2: 0 | BH2: 0 | BI2: 0 | BJ2: 0 | BK2: 0 | BL2: 0 | BM2: 0 | BN2: 0 | BO2: 0 | BP2: 0 | BQ2: 0 | BR2: 0 | BS2: 0 | BT2: 0 | BU2: 0 | BV2: 0 | BW2: 0 | BX2: 0 | BY2: 0 | BZ2: 0 | CA2: 0 | CB2: 0 | CC2: 0
A3: 강낭콩((울타리콩)) | B3: 0 | C3: 3.5 | D3: 0 | E3: 0 | F3: 0 | G3: 0 | H3: 0 | I3: 0 | J3: 0 | K3: 0 | L3: 0 | M3: 0 | N3: 0 | O3: 0 | P3: 0 | Q3: 0 | R3: 0 | S3: 0 | T3: 2.5 | U3: 8 | V3: 0 | W3: 0 | X3: 0 | Y3: 0 | Z3: 0 | AA3: 0 | AB3: 0 | AC3: 0 | AD3: 0 | AE3: 0 | AF3: 0 | AG3: 0 | AH3: 0 | AI3: 0 | AJ3: 3 | AK3: 0 | AL3: 0 | AM3: 0 | AN3: 0 | AO3: 0 | AP3: 0 | AQ3: 0 | AR3: 0 | AS3: 0 | AT3: 0 | AU3: 0 | AV3: 0 | AW3: 0 | AX3: 0 | AY3: 0 | BA3: 0 | BB3: 0 | BC3: 0 | BD3: 0 | BE3: 0 | BF3: 0 | BG3: 0 | BH3: 0 | BI3: 0 | BJ3: 0 | BK3: 0 | BL3: 0 | BM3: 0 | BN3: 0 | BO3: 0 | BP3: 0 | BQ3: 0 | BR3: 0 | BS3: 0 | BT3: 0 | BU3: 0 | BV3: 0 | BW3: 0 | BX3: 0 | BY3: 0 | BZ3: 0 | CA3: 0 | CB3: 0 | CC3: 1.8
A4: 건조딸기다이스(외국산) | B4: 0 | C4: 0 | D4: 0 | E4: 0 | F4: 0 | G4: 0 | H4: 0 | I4: 0.9 | J4: 0 | K4: 0 | L4: 0 | M4: 0 | N4: 0 | O4: 0 | P4: 0 | Q4: 0 | R4: 0 | S4: 0 | T4: 0 | U4: 0 | V4: 0 | W4: 0 | X4: 0 | Y4: 0 | Z4: 0 | AA4: 0 | AB4: 0 | AC4: 0 | AD4: 0 | AE4: 0 | AF4: 0 | AG4: 0 | AH4: 0 | AI4: 0 | AJ4: 0 | AK4: 0 | AL4: 0 | AM4: 0 | AN4: 0 | AO4: 0 | AP4: 0 | AQ4: 0 | AR4: 0 | AS4: 0 | AT4: 0 | AU4: 0 | AV4: 0 | AW4: 0 | AX4: 0 | AY4: 0 | BA4: 0 | BB4: 0 | BC4: 0 | BD4: 0 | BE4: 0 | BF4: 0 | BG4: 0 | BH4: 0 | BI4: 0 | BJ4: 0 | BK4: 0 | BL4: 0 | BM4: 0 | BN4: 0 | BO4: 0 | BP4: 0 | BQ4: 0 | BR4: 0 | BS4: 0 | BT4: 0 | BU4: 0 | BV4: 0 | BW4: 0 | BX4: 0 | BY4: 0 | BZ4: 0 | CA4: 0 | CB4: 0 | CC4: 0
A5: 건포도 | B5: 0 | C5: 0 | D5: 0 | E5: 0 | F5: 0 | G5: 1.2 | H5: 1.7 | I5: 0 | J5: 0 | K5: 0 | L5: 0 | M5: 0 | N5: 0 | O5: 0 | P5: 0 | Q5: 0 | R5: 0 | S5: 0 | T5: 0 | U5: 0 | V5: 0 | W5: 0 | X5: 0 | Y5: 0 | Z5: 0 | AA5: 0 | AB5: 0 | AC5: 0 | AD5: 0 | AE5: 0 | AF5: 0 | AG5: 0 | AH5: 0 | AI5: 0 | AJ5: 0 | AK5: 0 | AL5: 0 | AM5: 0 | AN5: 0 | AO5: 0 | AP5: 0 | AQ5: 0 | AR5: 0 | AS5: 0 | AT5: 0 | AU5: 0 | AV5: 0 | AW5: 0 | AX5: 0 | AY5: 0 | BA5: 0 | BB5: 0 | BC5: 0 | BD5: 0 | BE5: 0 | BF5: 0 | BG5: 0 | BH5: 0 | BI5: 0 | BJ5: 0 | BK5: 0 | BL5: 0 | BM5: 0 | BN5: 0 | BO5: 0 | BP5: 0 | BQ5: 0 | BR5: 0 | BS5: 0 | BT5: 0 | BU5: 0 | BV5: 0 | BW5: 0 | BX5: 0 | BY5: 0 | BZ5: 0 | CA5: 0 | CB5: 0 | CC5: 0
A6: 건호박채(중국산) | B6: 0.4 | C6: 0 | D6: 0 | E6: 0 | F6: 2 | G6: 2.3 | H6: 0 | I6: 0 | J6: 0 | K6: 0 | L6: 0 | M6: 0 | N6: 0 | O6: 0 | P6: 0 | Q6: 0 | R6: 0 | S6: 0 | T6: 1.6 | U6: 5 | V6: 0 | W6: 0 | X6: 0.4 | Y6: 0 | Z6: 0 | AA6: 0 | AB6: 0 | AC6: 0 | AD6: 0 | AE6: 0 | AF6: 0 | AG6: 0 | AH6: 0 | AI6: 0 | AJ6: 0 | AK6: 0 | AL6: 0 | AM6: 0 | AN6: 0 | AO6: 0 | AP6: 0 | AQ6: 0 | AR6: 0 | AS6: 0 | AT6: 0 | AU6: 1.2 | AV6: 0 | AW6: 0 | AX6: 0 | AY6: 0 | BA6: 0 | BB6: 0 | BC6: 2.7 | BD6: 0 | BE6: 0 | BF6: 0 | BG6: 0 | BH6: 0 | BI6: 0 | BJ6: 0 | BK6: 0 | BL6: 0 | BM6: 0 | BN6: 0 | BO6: 0 | BP6: 0 | BQ6: 0 | BR6: 0 | BS6: 0 | BT6: 0 | BU6: 0 | BV6: 3.3 | BW6: 3.3 | BX6: 0 | BY6: 0 | BZ6: 2.6 | CA6: 0 | CB6: 0 | CC6: 0
A7: 검정깨(흑임자) | B7: 0 | C7: 0.4 | D7: 0 | E7: 0 | F7: 0 | G7: 0.3 | H7: 0.3 | I7: 0 | J7: 0 | K7: 0 | L7: 0 | M7: 0 | N7: 0 | O7: 0 | P7: 0 | Q7: 0 | R7: 0 | S7: 0 | T7: 0 | U7: 0 | V7: 0 | W7: 0 | X7: 0 | Y7: 0 | Z7: 0 | AA7: 0 | AB7: 0 | AC7: 0 | AD7: 0 | AE7: 0 | AF7: 0 | AG7: 0 | AH7: 0 | AI7: 0 | AJ7: 0 | AK7: 0 | AL7: 0 | AM7: 0 | AN7: 0 | AO7: 0 | AP7: 0 | AQ7: 0 | AR7: 0 | AS7: 0 | AT7: 0 | AU7: 0 | AV7: 0 | AW7: 0 | AX7: 0 | AY7: 0 | BA7: 0 | BB7: 0 | BC7: 0 | BD7: 0 | BE7: 0 | BF7: 0 | BG7: 0 | BH7: 0 | BI7: 0 | BJ7: 0 | BK7: 0 | BL7: 0 | BM7: 0 | BN7: 0 | BO7: 0 | BP7: 0 | BQ7: 0 | BR7: 0 | BS7: 0 | BT7: 0 | BU7: 0 | BV7: 0 | BW7: 0 | BX7: 0 | BY7: 0 | BZ7: 0 | CA7: 0 | CB7: 2.4 | CC7: 0.4
A8: 검정콩 | B8: 0 | C8: 3.5 | D8: 0 | E8: 0 | F8: 0 | G8: 0 | H8: 0 | I8: 0 | J8: 0 | K8: 0 | L8: 0 | M8: 0 | N8: 0 | O8: 0 | P8: 0 | Q8: 0 | R8: 0 | S8: 0 | T8: 2.5 | U8: 6 | V8: 0 | W8: 0 | X8: 0 | Y8: 0 | Z8: 0 | AA8: 0 | AB8: 0 | AC8: 13.4 | AD8: 0 | AE8: 0 | AF8: 0 | AG8: 0 | AH8: 0 | AI8: 0 | AJ8: 0 | AK8: 0 | AL8: 0 | AM8: 0 | AN8: 0 | AO8: 13.4 | AP8: 0 | AQ8: 0 | AR8: 0 | AS8: 0 | AT8: 0 | AU8: 0 | AV8: 0 | AW8: 0 | AX8: 0 | AY8: 0 | BA8: 0 | BB8: 0 | BC8: 0 | BD8: 0 | BE8: 0 | BF8: 0 | BG8: 0 | BH8: 0 | BI8: 0 | BJ8: 0 | BK8: 0 | BL8: 0 | BM8: 0 | BN8: 0 | BO8: 0 | BP8: 0 | BQ8: 0 | BR8: 0 | BS8: 0 | BT8: 0 | BU8: 0 | BV8: 0 | BW8: 0 | BX8: 0 | BY8: 0 | BZ8: 0 | CA8: 0 | CB8: 0 | CC8: 1.8
A9: 계피가루 | B9: 0 | C9: 0 | D9: 0 | E9: 0 | F9: 0 | G9: 0 | H9: 0 | I9: 0 | J9: 0 | K9: 0 | L9: 0 | M9: 0 | N9: 0 | O9: 0 | P9: 0 | Q9: 0 | R9: 0 | S9: 0 | T9: 0 | U9: 0 | V9: 0 | W9: 0 | X9: 0 | Y9: 0.4 | Z9: 0 | AA9: 0 | AB9: 0 | AC9: 0 | AD9: 0 | AE9: 0 | AF9: 0 | AG9: 0 | AH9: 0 | AI9: 0 | AJ9: 0 | AK9: 0 | AL9: 0 | AM9: 0 | AN9: 0 | AO9: 0 | AP9: 0 | AQ9: 0 | AR9: 0 | AS9: 0 | AT9: 0 | AU9: 0 | AV9: 0 | AW9: 0 | AX9: 0 | AY9: 0 | BA9: 0 | BB9: 0 | BC9: 0 | BD9: 0 | BE9: 0 | BF9: 0 | BG9: 0 | BH9: 0 | BI9: 0 | BJ9: 0 | BK9: 0 | BL9: 0 | BM9: 0 | BN9: 0 | BO9: 0 | BP9: 0 | BQ9: 0 | BR9: 0 | BS9: 0 | BT9: 0 | BU9: 0 | BV9: 0 | BW9: 0 | BX9: 0 | BY9: 0 | BZ9: 0 | CA9: 0 | CB9: 0 | CC9: 0
A10: 고구마가루 | B10: 0 | C10: 0 | D10: 0 | E10: 0 | F10: 0 | G10: 0 | H10: 0 | I10: 0 | J10: 2.5 | K10: 0 | L10: 0 | M10: 0 | N10: 0 | O10: 0 | P10: 0 | Q10: 0 | R10: 0 | S10: 0 | T10: 0 | U10: 0 | V10: 0 | W10: 0 | X10: 0 | Y10: 0 | Z10: 0 | AA10: 0 | AB10: 0 | AC10: 0 | AD10: 0 | AE10: 0 | AF10: 0 | AG10: 0 | AH10: 0 | AI10: 0 | AJ10: 0 | AK10: 0 | AL10: 0 | AM10: 0 | AN10: 0 | AO10: 0 | AP10: 0 | AQ10: 0 | AR10: 0 | AS10: 0 | AT10: 0 | AU10: 0 | AV10: 0 | AW10: 0 | AX10: 0 | AY10: 0 | AZ10: 0 | BA10: 0 | BB10: 0 | BC10: 0 | BD10: 0 | BE10: 0 | BF10: 0 | BG10: 0 | BH10: 0 | BI10: 0 | BJ10: 0 | BK10: 0 | BL10: 0 | BM10: 0 | BN10: 0 | BO10: 0 | BP10: 0 | BQ10: 0 | BR10: 0 | BS10: 0 | BT10: 0 | BU10: 0 | BV10: 0 | BW10: 0 | BX10: 0 | BY10: 0 | BZ10: 0 | CA10: 0 | CB10: 0 | CC10: 0
A11: 고구마무스 | B11: 0 | C11: 0 | D11: 0 | E11: 0 | F11: 0 | G11: 0 | H11: 0 | I11: 0 | J11: 4.64 | K11: 0 | L11: 0 | M11: 0 | N11: 0 | O11: 0 | P11: 0 | Q11: 0 | R11: 0 | S11: 0 | T11: 0 | U11: 0 | V11: 0 | W11: 0 | X11: 0 | Y11: 0 | Z11: 0 | AA11: 0 | AB11: 0 | AC11: 0 | AD11: 0 | AE11: 0 | AF11: 0 | AG11: 0 | AH11: 0 | AI11: 0 | AJ11: 0 | AK11: 0 | AL11: 0 | AM11: 0 | AN11: 0 | AO11: 0 | AP11: 0 | AQ11: 0 | AR11: 0 | AS11: 0 | AT11: 0 | AU11: 0 | AV11: 0 | AW11: 0 | AX11: 0 | AY11: 0 | BA11: 0 | BB11: 0 | BC11: 0 | BD11: 0 | BE11: 0 | BF11: 0 | BG11: 0 | BH11: 0 | BI11: 0 | BJ11: 0 | BK11: 0 | BL11: 0 | BM11: 0 | BN11: 0 | BO11: 0 | BP11: 0 | BQ11: 0 | BR11: 0 | BS11: 0 | BT11: 0 | BU11: 0 | BV11: 0 | BW11: 0 | BX11: 0 | BY11: 0 | BZ11: 0 | CA11: 0 | CB11: 0 | CC11: 0
A12: 고려엉겅퀴((곤드레)국내산) | B12: 0 | C12: 4.7 | D12: 0 | E12: 0 | F12: 0 | G12: 0 | H12: 0 | I12: 0 | J12: 0 | K12: 0 | L12: 0 | M12: 0 | N12: 0 | O12: 0 | P12: 0 | Q12: 0 | R12: 0 | S12: 0 | T12: 0 | U12: 0 | V12: 0 | W12: 0 | X12: 0 | Y12: 0 | Z12: 0 | AA12: 0 | AB12: 0 | AC12: 0 | AD12: 0 | AE12: 0 | AF12: 0 | AG12: 0 | AH12: 0 | AI12: 0 | AJ12: 0 | AK12: 0 | AL12: 0 | AM12: 0 | AN12: 0 | AO12: 0 | AP12: 0 | AQ12: 0 | AR12: 0 | AS12: 0 | AT12: 0 | AU12: 0 | AV12: 0 | AW12: 0 | AX12: 0 | AY12: 0 | BA12: 0 | BB12: 0 | BC12: 0 | BD12: 0 | BE12: 0 | BF12: 0 | BG12: 0 | BH12: 0 | BI12: 0 | BJ12: 0 | BK12: 0 | BL12: 0 | BM12: 0 | BN12: 0 | BO12: 0 | BP12: 0 | BQ12: 0 | BR12: 0 | BS12: 0 | BT12: 0 | BU12: 0 | BV12: 0 | BW12: 0 | BX12: 0 | BY12: 0 | BZ12: 0 | CA12: 0 | CB12: 0 | CC12: 0
A13: 기타가공품(복분자가루) | B13: 0 | C13: 0 | D13: 0 | E13: 0 | F13: 0 | G13: 0 | H13: 0 | I13: 0 | J13: 0 | K13: 0 | L13: 0 | M13: 0 | N13: 0 | O13: 0 | P13: 0 | Q13: 0 | R13: 1.1 | S13: 0 | T13: 0 | U13: 0 | V13: 0 | W13: 0 | X13: 0 | Y13: 0 | Z13: 0 | AA13: 0 | AB13: 0 | AC13: 0 | AD13: 0 | AE13: 0 | AF13: 0 | AG13: 0 | AH13: 0 | AI13: 0 | AJ13: 0 | AK13: 0 | AL13: 0 | AM13: 0 | AN13: 0 | AO13: 0 | AP13: 0 | AQ13: 0 | AR13: 0 | AS13: 0 | AT13: 0 | AU13: 0 | AV13: 0 | AW13: 0 | AX13: 0 | AY13: 0 | BA13: 0 | BB13: 0 | BC13: 0 | BD13: 0 | BE13: 0 | BF13: 0 | BG13: 0 | BH13: 0 | BI13: 0 | BJ13: 0 | BK13: 0 | BL13: 0 | BM13: 0 | BN13: 0 | BO13: 0 | BP13: 0 | BQ13: 0 | BR13: 0 | BS13: 0 | BT13: 0 | BU13: 0 | BV13: 0 | BW13: 0 | BX13: 0 | BY13: 0 | BZ13: 0 | CA13: 0 | CB13: 0 | CC13: 0
A14: 기타가공품(슈퍼소프트엠) | B14: 0 | C14: 0 | D14: 0 | E14: 0 | F14: 0 | G14: 0 | H14: 0 | I14: 0 | J14: 0 | K14: 0 | L14: 0 | M14: 0 | N14: 0 | O14: 0 | P14: 0 | Q14: 0 | R14: 0 | S14: 0 | T14: 0 | U14: 0 | V14: 0 | W14: 0 | X14: 0 | Y14: 0 | Z14: 0.7 | AA14: 0 | AB14: 0 | AC14: 0 | AD14: 0 | AE14: 0 | AF14: 0 | AG14: 0 | AH14: 0 | AI14: 0 | AJ14: 0 | AK14: 0 | AL14: 0 | AM14: 0 | AN14: 0 | AO14: 0 | AP14: 0 | AQ14: 0 | AR14: 0 | AS14: 0 | AT14: 0 | AU14: 0 | AV14: 0 | AW14: 0 | AX14: 0 | AY14: 0 | BA14: 0 | BB14: 0 | BC14: 0 | BD14: 0 | BE14: 0 | BF14: 0 | BG14: 0 | BH14: 0 | BI14: 0 | BJ14: 0 | BK14: 0 | BL14: 0 | BM14: 0 | BN14: 0 | BO14: 0 | BP14: 0 | BQ14: 0 | BR14: 0 | BS14: 0 | BT14: 0 | BU14: 0 | BV14: 0 | BW14: 0 | BX14: 0 | BY14: 0 | BZ14: 0 | CA14: 0 | CB14: 0 | CC14: 0
A15: 기타가공품(파인소프트 E-티) | B15: 0 | C15: 0 | D15: 0 | E15: 0 | F15: 0 | G15: 0 | H15: 0 | I15: 0 | J15: 0 | K15: 0 | L15: 0 | M15: 0 | N15: 0 | O15: 0 | P15: 0 | Q15: 0 | R15: 0 | S15: 0 | T15: 0 | U15: 0 | V15: 0 | W15: 0 | X15: 0 | Y15: 0 | Z15: 0.7 | AA15: 0 | AB15: 0 | AC15: 0 | AD15: 0 | AE15: 0 | AF15: 0 | AG15: 0 | AH15: 0 | AI15: 0 | AJ15: 0 | AK15: 0 | AL15: 0 | AM15: 0 | AN15: 0 | AO15: 0 | AP15: 0 | AQ15: 0 | AR15: 0 | AS15: 0 | AT15: 0 | AU15: 0 | AV15: 0 | AW15: 0 | AX15: 0 | AY15: 0 | BA15: 0 | BB15: 0 | BC15: 0 | BD15: 0 | BE15: 0 | BF15: 0 | BG15: 0 | BH15: 0 | BI15: 0 | BJ15: 0 | BK15: 0 | BL15: 0 | BM15: 0 | BN15: 0 | BO15: 0 | BP15: 0 | BQ15: 1.1 | BR15: 0 | BS15: 0 | BT15: 0 | BU15: 0 | BV15: 0 | BW15: 0 | BX15: 0 | BY15: 0 | BZ15: 0 | CA15: 0 | CB15: 0 | CC15: 0
A16: 기타가공품(프리미엄카스테라가루) | B16: 0 | C16: 0 | D16: 0 | E16: 0 | F16: 0 | G16: 0 | H16: 0 | I16: 0 | J16: 2.96 | K16: 2.96 | L16: 2.96 | M16: 2.96 | N16: 2.96 | O16: 2.96 | P16: 0 | Q16: 0 | R16: 0 | S16: 0 | T16: 0 | U16: 0 | V16: 0 | W16: 0 | X16: 0 | Y16: 0 | Z16: 0 | AA16: 0 | AB16: 0 | AC16: 0 | AD16: 0 | AE16: 0 | AF16: 0 | AG16: 0 | AH16: 0 | AI16: 0 | AJ16: 0 | AK16: 0 | AL16: 0 | AM16: 0 | AN16: 0 | AO16: 0 | AP16: 0 | AQ16: 0 | AR16: 0 | AS16: 0 | AT16: 0 | AU16: 0 | AV16: 0 | AW16: 0 | AX16: 0 | AY16: 0 | BA16: 0 | BB16: 0 | BC16: 5.8 | BD16: 15.1 | BE16: 3 | BF16: 3 | BG16: 2.9 | BH16: 2.9 | BI16: 3 | BJ16: 11 | BK16: 0 | BL16: 0 | BM16: 0 | BN16: 0 | BO16: 0 | BP16: 0 | BQ16: 0 | BR16: 0 | BS16: 0 | BT16: 0 | BU16: 0 | BV16: 0 | BW16: 0 | BX16: 0 | BY16: 0 | BZ16: 0 | CA16: 0 | CB16: 0 | CC16: 0 | CD16: 7 | CE16: 7
A17: 기타가공품(흑임자가루) | B17: 0 | C17: 0 | D17: 0 | E17: 0 | F17: 0 | G17: 0 | H17: 0 | I17: 0 | J17: 0 | K17: 0 | L17: 0 | M17: 0 | N17: 0 | O17: 7.14 | P17: 0 | Q17: 0 | R17: 0 | S17: 0 | T17: 0 | U17: 0 | V17: 0 | W17: 0 | X17: 0 | Y17: 1.6 | Z17: 0 | AA17: 0 | AB17: 0 | AC17: 0 | AD17: 0 | AE17: 0 | AF17: 0 | AG17: 0 | AH17: 0 | AI17: 0 | AJ17: 0 | AK17: 0 | AL17: 0 | AM17: 0 | AN17: 0 | AO17: 0 | AP17: 0 | AQ17: 0 | AR17: 0 | AS17: 0 | AT17: 0 | AU17: 0 | AV17: 0 | AW17: 0 | AX17: 0 | AY17: 0 | BA17: 0 | BB17: 0 | BC17: 0 | BD17: 0 | BE17: 0 | BF17: 0 | BG17: 0 | BH17: 0 | BI17: 0 | BJ17: 0 | BK17: 0 | BL17: 0 | BM17: 0 | BN17: 0 | BO17: 0 | BP17: 0 | BQ17: 0 | BR17: 0 | BS17: 0 | BT17: 0 | BU17: 0 | BV17: 0 | BW17: 0 | BX17: 0 | BY17: 0 | BZ17: 0 | CA17: 0 | CB17: 2.4 | CC17: 3
A18: 기타설탕(흑설탕) | B18: 0 | C18: 0 | D18: 8.4 | E18: 0 | F18: 0 | G18: 0 | H18: 0 | I18: 0 | J18: 0 | K18: 0 | L18: 0 | M18: 0 | N18: 0 | O18: 0 | P18: 0 | Q18: 0 | R18: 0 | S18: 0 | T18: 0 | U18: 0 | V18: 0 | W18: 0 | X18: 0 | Y18: 0 | Z18: 0 | AA18: 0 | AB18: 0 | AC18: 10 | AD18: 0 | AE18: 0 | AF18: 0 | AG18: 0 | AH18: 0 | AI18: 0 | AJ18: 0 | AK18: 0 | AL18: 0 | AM18: 0 | AN18: 0 | AO18: 10 | AP18: 0 | AQ18: 0 | AR18: 0 | AS18: 0 | AT18: 0 | AU18: 0 | AV18: 0 | AW18: 0 | AX18: 0 | AY18: 0 | BA18: 0 | BB18: 0 | BC18: 0 | BD18: 0 | BE18: 0 | BF18: 0 | BG18: 0 | BH18: 0 | BI18: 0 | BJ18: 0 | BK18: 0 | BL18: 0 | BM18: 0 | BN18: 0 | BO18: 0 | BP18: 0 | BQ18: 0 | BR18: 0 | BS18: 0 | BT18: 0 | BU18: 7.6 | BV18: 2 | BW18: 0 | BX18: 0 | BY18: 0 | BZ18: 0 | CA18: 0 | CB18: 0 | CC18: 0
A19: 냉동쑥(국내산) | B19: 0.9 | C19: 0 | D19: 0 | E19: 0 | F19: 0 | G19: 0 | H19: 0 | I19: 0 | J19: 0 | K19: 0 | L19: 0 | M19: 0 | N19: 0 | O19: 0 | P19: 0 | Q19: 0 | R19: 0 | S19: 0 | T19: 0 | U19: 0 | V19: 0 | W19: 0 | X19: 1.3 | Y19: 0 | Z19: 8.8 | AA19: 0 | AB19: 0 | AC19: 0 | AD19: 0 | AE19: 0 | AF19: 2 | AG19: 0 | AH19: 4 | AI19: 12.1 | AJ19: 67 | AK19: 1.9 | AL19: 7.6 | AM19: 13.6 | AN19: 8.8 | AO19: 0 | AP19: 1.99 | AQ19: 0 | AR19: 0 | AS19: 0 | AT19: 0 | AU19: 0 | AV19: 0 | AW19: 0 | AX19: 0 | AY19: 0 | BA19: 0 | BB19: 0 | BC19: 0 | BD19: 0 | BE19: 9 | BF19: 0 | BG19: 2.9 | BH19: 0 | BI19: 0 | BJ19: 0 | BK19: 2.3 | BL19: 0 | BM19: 3.3 | BN19: 2 | BO19: 0 | BP19: 0 | BQ19: 0 | BR19: 0 | BS19: 2.9 | BT19: 0 | BU19: 0 | BV19: 0 | BW19: 0 | BX19: 0 | BY19: 0 | BZ19: 0 | CA19: 0 | CB19: 0 | CC19: 0 | CE19: 5.6
A20: 냉동증숙고구마(중국산) | B20: 0 | C20: 0 | D20: 0 | E20: 0 | F20: 0 | G20: 0 | H20: 0 | I20: 0 | J20: 0 | K20: 0 | L20: 0 | M20: 0 | N20: 0 | O20: 0 | P20: 0 | Q20: 0 | R20: 0 | S20: 0 | T20: 0 | U20: 0 | V20: 0 | W20: 0 | X20: 0 | Y20: 0 | Z20: 0 | AA20: 0 | AB20: 0 | AC20: 0 | AD20: 0 | AE20: 0 | AF20: 0 | AG20: 0 | AH20: 0 | AI20: 0 | AJ20: 0 | AK20: 0 | AL20: 0 | AM20: 0 | AN20: 0 | AO20: 0 | AP20: 0 | AQ20: 0 | AR20: 0 | AS20: 0 | AT20: 0 | AU20: 6 | AV20: 0 | AW20: 0 | AX20: 0 | AY20: 0 | BA20: 0 | BB20: 0 | BC20: 0 | BD20: 0 | BE20: 0 | BF20: 0 | BG20: 0 | BH20: 0 | BI20: 0 | BJ20: 0 | BK20: 0 | BL20: 0 | BM20: 0 | BN20: 0 | BO20: 0 | BP20: 0 | BQ20: 0 | BR20: 0 | BS20: 0 | BT20: 0 | BU20: 0 | BV20: 0 | BW20: 0 | BX20: 0 | BY20: 0 | BZ20: 0 | CA20: 0 | CB20: 0 | CC20: 0
A21: 녹차가루 | B21: 0 | C21: 0 | D21: 0 | E21: 0 | F21: 0 | G21: 0 | H21: 0 | I21: 0 | J21: 0 | K21: 0 | L21: 7.14 | M21: 0 | N21: 0 | O21: 0 | P21: 0 | Q21: 0 | R21: 0 | S21: 0 | T21: 0 | U21: 0 | V21: 0 | W21: 0 | X21: 0 | Y21: 0 | Z21: 0 | AA21: 0 | AB21: 0 | AC21: 0 | AD21: 0 | AE21: 0 | AF21: 0 | AG21: 0 | AH21: 0 | AI21: 0 | AJ21: 0 | AK21: 0 | AL21: 0 | AM21: 0 | AN21: 0 | AO21: 0 | AP21: 0 | AQ21: 0 | AR21: 0 | AS21: 0 | AT21: 0 | AU21: 0 | AV21: 0 | AW21: 0 | AX21: 0 | AY21: 0 | BA21: 0 | BB21: 0 | BC21: 0 | BD21: 0 | BE21: 0 | BF21: 0 | BG21: 0 | BH21: 0 | BI21: 0 | BJ21: 0 | BK21: 0 | BL21: 0 | BM21: 0 | BN21: 0 | BO21: 0 | BP21: 0 | BQ21: 0 | BR21: 0 | BS21: 0 | BT21: 0 | BU21: 0 | BV21: 0 | BW21: 0 | BX21: 0 | BY21: 0 | BZ21: 0 | CA21: 0 | CB21: 0 | CC21: 0
A22: 다크초콜릿 컴파운드칩 | B22: 0 | C22: 0 | D22: 0 | E22: 0 | F22: 0 | G22: 0 | H22: 0 | I22: 0 | J22: 0 | K22: 0 | L22: 0 | M22: 3.57 | N22: 0 | O22: 0 | P22: 0 | Q22: 0 | R22: 0 | S22: 0 | T22: 0 | U22: 0 | V22: 0 | W22: 0 | X22: 0 | Y22: 0 | Z22: 0 | AA22: 0 | AB22: 0 | AC22: 0 | AD22: 0 | AE22: 0 | AF22: 0 | AG22: 0 | AH22: 0 | AI22: 0 | AJ22: 0 | AK22: 0 | AL22: 0 | AM22: 0 | AN22: 0 | AO22: 0 | AP22: 0 | AQ22: 0 | AR22: 0 | AS22: 0 | AT22: 0 | AU22: 0 | AV22: 0 | AW22: 0 | AX22: 0 | AY22: 0 | BA22: 0 | BB22: 0 | BC22: 0 | BD22: 0 | BE22: 0 | BF22: 0 | BG22: 0 | BH22: 0 | BI22: 0 | BJ22: 0 | BK22: 0 | BL22: 0 | BM22: 0 | BN22: 0 | BO22: 0 | BP22: 0 | BQ22: 0 | BR22: 0 | BS22: 0 | BT22: 0 | BU22: 0 | BV22: 0 | BW22: 0 | BX22: 0 | BY22: 0 | BZ22: 0 | CA22: 0 | CB22: 0 | CC22: 0
A23: 단호박분말(중국산) | B23: 0.8 | C23: 0 | D23: 0 | E23: 0 | F23: 0.8 | G23: 1.2 | H23: 0 | I23: 0 | J23: 0 | K23: 0 | L23: 0 | M23: 0 | N23: 0 | O23: 0 | P23: 0 | Q23: 1.1 | R23: 0 | S23: 0 | T23: 0 | U23: 0 | V23: 0 | W23: 0 | X23: 0.7 | Y23: 1.6 | Z23: 0 | AA23: 0 | AB23: 0 | AC23: 0 | AD23: 0 | AE23: 0 | AF23: 0 | AG23: 3 | AH23: 0 | AI23: 0 | AJ23: 0 | AK23: 0 | AL23: 0 | AM23: 0 | AN23: 0 | AO23: 0 | AP23: 0.2 | AQ23: 0 | AR23: 0 | AS23: 0 | AT23: 0 | AU23: 0 | AV23: 0 | AW23: 0 | AX23: 0 | AY23: 2.4 | BA23: 0 | BB23: 0 | BC23: 3.3 | BD23: 0 | BE23: 0 | BF23: 0 | BG23: 0 | BH23: 1.7 | BI23: 0 | BJ23: 2.2 | BK23: 0 | BL23: 0 | BM23: 0 | BN23: 0 | BO23: 0 | BP23: 0 | BQ23: 0 | BR23: 0 | BS23: 0 | BT23: 1.7 | BU23: 1.5 | BV23: 2 | BW23: 2 | BX23: 1.7 | BY23: 1.3 | BZ23: 3.1 | CA23: 0 | CB23: 0 | CC23: 0
A24: 당류가공품(단호박농축액) | B24: 0.04 | C24: 0 | D24: 0 | E24: 0 | F24: 0 | G24: 0.6 | H24: 0 | I24: 0 | J24: 0 | K24: 0 | L24: 0 | M24: 0 | N24: 0 | O24: 0 | P24: 0 | Q24: 0 | R24: 0 | S24: 0 | T24: 0 | U24: 0 | V24: 0 | W24: 0 | X24: 0.04 | Y24: 0 | Z24: 0 | AA24: 0 | AB24: 0 | AC24: 0 | AD24: 0 | AE24: 0 | AF24: 0 | AG24: 0 | AH24: 0 | AI24: 0 | AJ24: 0 | AK24: 0 | AL24: 0 | AM24: 0 | AN24: 0 | AO24: 0 | AP24: 0 | AQ24: 0 | AR24: 0 | AS24: 0 | AT24: 0 | AU24: 0 | AV24: 0 | AW24: 0 | AX24: 0 | AY24: 1.6 | BA24: 0 | BB24: 0 | BC24: 0.2 | BD24: 0 | BE24: 0 | BF24: 0 | BG24: 0 | BH24: 0.1 | BI24: 0 | BJ24: 0.1 | BK24: 0 | BL24: 0 | BM24: 0 | BN24: 0 | BO24: 0 | BP24: 0 | BQ24: 0 | BR24: 0 | BS24: 0 | BT24: 0.1 | BU24: 0 | BV24: 0 | BW24: 0 | BX24: 0 | BY24: 0 | BZ24: 0.2 | CA24: 0 | CB24: 0 | CC24: 0
A25: 당류가공품(알룰로스,에리스리톨,스테비올배당체혼합) | B25: 0 | C25: 0 | D25: 0 | E25: 0 | F25: 0 | G25: 0 | H25: 0 | I25: 0 | J25: 0 | K25: 0 | L25: 0 | M25: 0 | N25: 0 | O25: 0 | P25: 0 | Q25: 0 | R25: 0 | S25: 0 | T25: 0 | U25: 0 | V25: 0 | W25: 0 | X25: 0 | Y25: 0 | Z25: 0 | AA25: 0 | AB25: 0 | AC25: 0 | AD25: 0 | AE25: 0 | AF25: 0 | AG25: 0 | AH25: 0 | AI25: 0 | AJ25: 0 | AK25: 0 | AL25: 0 | AM25: 0 | AN25: 0 | AO25: 0 | AP25: 0 | AQ25: 0 | AR25: 0 | AS25: 0 | AT25: 0 | AU25: 0 | AV25: 0 | AW25: 1.7 | AX25: 0 | AY25: 0 | BA25: 0 | BB25: 0 | BC25: 0 | BD25: 0 | BE25: 0 | BF25: 0 | BG25: 0 | BH25: 0 | BI25: 0 | BJ25: 0 | BK25: 0 | BL25: 0 | BM25: 0 | BN25: 0 | BO25: 0 | BP25: 0 | BQ25: 0 | BR25: 0 | BS25: 0 | BT25: 0 | BU25: 0 | BV25: 0 | BW25: 0 | BX25: 0 | BY25: 0 | BZ25: 0 | CA25: 0 | CB25: 0 | CC25: 0
A26: 당류가공품(알룰로스제로파우더) | B26: 0 | C26: 0 | D26: 0 | E26: 0 | F26: 0 | G26: 0 | H26: 0 | I26: 0 | J26: 0 | K26: 0 | L26: 0 | M26: 0 | N26: 0 | O26: 0 | P26: 0 | Q26: 0 | R26: 0 | S26: 0 | T26: 0 | U26: 0 | V26: 0 | W26: 0 | X26: 0 | Y26: 0 | Z26: 0 | AA26: 0 | AB26: 0 | AC26: 0 | AD26: 0 | AE26: 0 | AF26: 0 | AG26: 0 | AH26: 0 | AI26: 0 | AJ26: 0 | AK26: 0 | AL26: 0 | AM26: 0 | AN26: 0 | AO26: 0 | AP26: 0 | AQ26: 0 | AR26: 0 | AS26: 0 | AT26: 0 | AU26: 0 | AV26: 0 | AW26: 0 | AX26: 1.7 | AY26: 0 | BA26: 0 | BB26: 0 | BC26: 0 | BD26: 0 | BE26: 0 | BF26: 0 | BG26: 0 | BH26: 0 | BI26: 0 | BJ26: 0 | BK26: 0 | BL26: 0 | BM26: 0 | BN26: 0 | BO26: 0 | BP26: 0 | BQ26: 0 | BR26: 0 | BS26: 0 | BT26: 0 | BU26: 0 | BV26: 0 | BW26: 0 | BX26: 0 | BY26: 0 | BZ26: 0 | CA26: 0 | CB26: 0 | CC26: 0
A27: 당절임(완두배기) | B27: 0 | C27: 0 | D27: 0 | E27: 0 | F27: 0 | G27: 0 | H27: 0 | I27: 0 | J27: 0 | K27: 0 | L27: 0 | M27: 0 | N27: 0 | O27: 0 | P27: 0 | Q27: 0 | R27: 0 | S27: 0 | T27: 0 | U27: 0 | V27: 0 | W27: 0 | X27: 0 | Y27: 0 | Z27: 0 | AA27: 0 | AB27: 0 | AC27: 0 | AD27: 0 | AE27: 0 | AF27: 0 | AG27: 0 | AH27: 0 | AI27: 0 | AJ27: 0 | AK27: 0 | AL27: 0 | AM27: 0 | AN27: 0 | AO27: 0 | AP27: 0 | AQ27: 24 | AR27: 0 | AS27: 0 | AT27: 0 | AU27: 0 | AV27: 0 | AW27: 0 | AX27: 0 | AY27: 0 | BA27: 0 | BB27: 0 | BC27: 0 | BD27: 0 | BE27: 0 | BF27: 0 | BG27: 0 | BH27: 0 | BI27: 0 | BJ27: 0 | BK27: 0 | BL27: 0 | BM27: 0 | BN27: 0 | BO27: 0 | BP27: 0 | BQ27: 0 | BR27: 0 | BS27: 0 | BT27: 0 | BU27: 0 | BV27: 0 | BW27: 0 | BX27: 0 | BY27: 0 | BZ27: 0 | CA27: 0 | CB27: 0 | CC27: 0
A28: 대추농축액 | B28: 0 | C28: 0 | D28: 0 | E28: 0 | F28: 0 | G28: 0 | H28: 2.9 | I28: 0 | J28: 0 | K28: 0 | L28: 0 | M28: 0 | N28: 0 | O28: 0 | P28: 0 | Q28: 0 | R28: 0 | S28: 0 | T28: 0 | U28: 0 | V28: 0 | W28: 0 | X28: 0 | Y28: 0 | Z28: 0 | AA28: 0 | AB28: 0 | AC28: 0 | AD28: 0 | AE28: 0 | AF28: 0 | AG28: 0 | AH28: 0 | AI28: 0 | AJ28: 0 | AK28: 0 | AL28: 0 | AM28: 0 | AN28: 0 | AO28: 0 | AP28: 0 | AQ28: 0 | AR28: 0 | AS28: 0 | AT28: 0 | AU28: 0 | AV28: 0 | AW28: 0 | AX28: 0 | AY28: 0 | BA28: 0 | BB28: 0 | BC28: 0 | BD28: 0 | BE28: 0 | BF28: 0 | BG28: 0 | BH28: 0 | BI28: 0 | BJ28: 0 | BK28: 0 | BL28: 0 | BM28: 0 | BN28: 0 | BO28: 0 | BP28: 0 | BQ28: 0 | BR28: 0 | BS28: 0 | BT28: 0 | BU28: 0 | BV28: 0 | BW28: 0 | BX28: 0 | BY28: 0 | BZ28: 0 | CA28: 0 | CB28: 0 | CC28: 0
A29: 대추채(국내산) | B29: 0 | C29: 0 | D29: 0 | E29: 0 | F29: 0 | G29: 1.2 | H29: 1.2 | I29: 0 | J29: 0 | K29: 0 | L29: 0 | M29: 0 | N29: 0 | O29: 0 | P29: 0 | Q29: 0 | R29: 0 | S29: 0 | T29: 0 | U29: 0 | V29: 0 | W29: 0 | X29: 0 | Y29: 0 | Z29: 0 | AA29: 0 | AB29: 0 | AC29: 0 | AD29: 0 | AE29: 0 | AF29: 0 | AG29: 0 | AH29: 0 | AI29: 0 | AJ29: 0 | AK29: 0 | AL29: 1.5 | AM29: 0 | AN29: 0 | AO29: 0 | AP29: 0 | AQ29: 0 | AR29: 0 | AS29: 0 | AT29: 0 | AU29: 0 | AV29: 0 | AW29: 0 | AX29: 0 | AY29: 0 | BA29: 0 | BB29: 0 | BC29: 0 | BD29: 0 | BE29: 0 | BF29: 0 | BG29: 0 | BH29: 0 | BI29: 0 | BJ29: 0 | BK29: 0 | BL29: 0 | BM29: 0 | BN29: 0 | BO29: 0 | BP29: 0 | BQ29: 0 | BR29: 0 | BS29: 0 | BT29: 0 | BU29: 0 | BV29: 0 | BW29: 0 | BX29: 0 | BY29: 0 | BZ29: 0 | CA29: 0 | CB29: 0 | CC29: 0
A30: 동부(미얀마산) | B30: 0 | C30: 0 | D30: 0 | E30: 0 | F30: 0 | G30: 0 | H30: 0 | I30: 0 | J30: 0 | K30: 0 | L30: 0 | M30: 0 | N30: 0 | O30: 0 | P30: 0 | Q30: 0 | R30: 0 | S30: 0 | T30: 0 | U30: 0 | V30: 0 | W30: 0 | X30: 0 | Y30: 0 | Z30: 0 | AA30: 20 | AB30: 0 | AC30: 0 | AD30: 0 | AE30: 0 | AF30: 0 | AG30: 0 | AH30: 0 | AI30: 0 | AJ30: 0 | AK30: 0 | AL30: 0 | AM30: 0 | AN30: 0 | AO30: 0 | AP30: 0 | AQ30: 0 | AR30: 0 | AS30: 0 | AT30: 0 | AU30: 0 | AV30: 0 | AW30: 0 | AX30: 0 | AY30: 0 | BA30: 0 | BB30: 0 | BC30: 0 | BD30: 0 | BE30: 0 | BF30: 0 | BG30: 0 | BH30: 0 | BI30: 0 | BJ30: 15.4 | BK30: 14 | BL30: 8 | BM30: 0 | BN30: 12.4 | BO30: 0 | BP30: 0 | BQ30: 0 | BR30: 0 | BS30: 0 | BT30: 0 | BU30: 0 | BV30: 0 | BW30: 0 | BX30: 0 | BY30: 0 | BZ30: 0 | CA30: 0 | CB30: 0 | CC30: 0 | CD30: 8 | CE30: 7.5
A31: 두류가공품(백옥앙금) | B31: 0 | C31: 0 | D31: 0 | E31: 0 | F31: 0 | G31: 0 | H31: 0 | I31: 0 | J31: 0 | K31: 0 | L31: 0 | M31: 0 | N31: 0 | O31: 0 | P31: 0 | Q31: 0 | R31: 0 | S31: 0 | T31: 0 | U31: 0 | V31: 0 | W31: 0 | X31: 0 | Y31: 0 | Z31: 0 | AA31: 25 | AB31: 0 | AC31: 0 | AD31: 0 | AE31: 0 | AF31: 0 | AG31: 0 | AH31: 0 | AI31: 0 | AJ31: 0 | AK31: 0 | AL31: 0 | AM31: 0 | AN31: 0 | AO31: 0 | AP31: 0 | AQ31: 0 | AR31: 0 | AS31: 0 | AT31: 0 | AU31: 0 | AV31: 0 | AW31: 0 | AX31: 0 | AY31: 0 | BA31: 0 | BB31: 0 | BC31: 0 | BD31: 0 | BE31: 0 | BF31: 0 | BG31: 0 | BH31: 0 | BI31: 0 | BJ31: 0 | BK31: 28 | BL31: 33 | BM31: 0 | BN31: 0 | BO31: 0 | BP31: 0 | BQ31: 0 | BR31: 0 | BS31: 0 | BT31: 0 | BU31: 0 | BV31: 0 | BW31: 0 | BX31: 0 | BY31: 0 | BZ31: 0 | CA31: 0 | CB31: 0 | CC31: 0
A32: 두류가공품(콩고물) | B32: 0 | C32: 0 | D32: 0 | E32: 3 | F32: 0 | G32: 0 | H32: 0 | I32: 0 | J32: 0 | K32: 0 | L32: 0 | M32: 0 | N32: 0 | O32: 0 | P32: 0 | Q32: 0 | R32: 0 | S32: 0 | T32: 0 | U32: 0 | V32: 0 | W32: 3.6 | X32: 5.1 | Y32: 0 | Z32: 0 | AA32: 0 | AB32: 0 | AC32: 0 | AD32: 0 | AE32: 0 | AF32: 0 | AG32: 0 | AH32: 0 | AI32: 0 | AJ32: 0 | AK32: 0.2 | AL32: 0 | AM32: 3.4 | AN32: 0 | AO32: 0 | AP32: 0.35 | AQ32: 0 | AR32: 0 | AS32: 0 | AT32: 4.2 | AU32: 0 | AV32: 0.2 | AW32: 0 | AX32: 0 | AY32: 0 | BA32: 0 | BB32: 0 | BC32: 0 | BD32: 0 | BE32: 0 | BF32: 0 | BG32: 0 | BH32: 0 | BI32: 0 | BJ32: 0 | BK32: 3 | BL32: 7 | BM32: 3 | BN32: 2.7 | BO32: 0 | BP32: 3 | BQ32: 0 | BR32: 0 | BS32: 0 | BT32: 0 | BU32: 0 | BV32: 0 | BW32: 0 | BX32: 0 | BY32: 0.2 | BZ32: 3.7 | CA32: 0.2 | CB32: 0 | CC32: 0
A33: 두류가공품(통팥고물) | B33: 0 | C33: 0 | D33: 0 | E33: 0 | F33: 0 | G33: 0 | H33: 0 | I33: 0 | J33: 0 | K33: 0 | L33: 0 | M33: 0 | N33: 0 | O33: 0 | P33: 0 | Q33: 0 | R33: 0 | S33: 0 | T33: 0 | U33: 0 | V33: 0 | W33: 0 | X33: 0 | Y33: 0 | Z33: 0 | AA33: 0 | AB33: 0 | AC33: 0 | AD33: 0 | AE33: 0 | AF33: 0 | AG33: 0 | AH33: 0 | AI33: 0 | AJ33: 0 | AK33: 0 | AL33: 0 | AM33: 0 | AN33: 0 | AO33: 0 | AP33: 0 | AQ33: 20 | AR33: 0 | AS33: 0 | AT33: 0 | AU33: 0 | AV33: 0 | AW33: 0 | AX33: 0 | AY33: 0 | BA33: 0 | BB33: 0 | BC33: 0 | BD33: 0 | BE33: 0 | BF33: 0 | BG33: 0 | BH33: 0 | BI33: 0 | BJ33: 0 | BK33: 0 | BL33: 0 | BM33: 0 | BN33: 0 | BO33: 0 | BP33: 0 | BQ33: 0 | BR33: 0 | BS33: 0 | BT33: 0 | BU33: 0 | BV33: 30 | BW33: 30 | BX33: 0 | BY33: 0 | BZ33: 0 | CA33: 0 | CB33: 0 | CC33: 0
A34: 딸기레진 | B34: 0 | C34: 0 | D34: 0 | E34: 0 | F34: 0 | G34: 0 | H34: 0 | I34: 0.1 | J34: 0 | K34: 3.57 | L34: 0 | M34: 0 | N34: 0 | O34: 0 | P34: 0 | Q34: 0 | R34: 0 | S34: 0 | T34: 0 | U34: 0 | V34: 0 | W34: 0 | X34: 0 | Y34: 0 | Z34: 0 | AA34: 0 | AB34: 0 | AC34: 0 | AD34: 0 | AE34: 0 | AF34: 0 | AG34: 0 | AH34: 0 | AI34: 0 | AJ34: 0 | AK34: 0 | AL34: 0 | AM34: 0 | AN34: 0 | AO34: 0 | AP34: 0 | AQ34: 0 | AR34: 0 | AS34: 0 | AT34: 0 | AU34: 0 | AV34: 0 | AW34: 0 | AX34: 0 | AY34: 0 | BA34: 0 | BB34: 0 | BC34: 0 | BD34: 0 | BE34: 0 | BF34: 0 | BG34: 0 | BH34: 0 | BI34: 0 | BJ34: 0 | BK34: 0 | BL34: 0 | BM34: 0 | BN34: 0 | BO34: 0 | BP34: 0 | BQ34: 0 | BR34: 0 | BS34: 0 | BT34: 0 | BU34: 0 | BV34: 0 | BW34: 0 | BX34: 0 | BY34: 0 | BZ34: 0 | CA34: 0 | CB34: 0 | CC34: 0
A35: 딸기분말(스트로우베리에이드(분말)) | B35: 0 | C35: 0 | D35: 0 | E35: 0 | F35: 0 | G35: 0 | H35: 0 | I35: 1.4 | J35: 0 | K35: 0 | L35: 0 | M35: 0 | N35: 0 | O35: 0 | P35: 0 | Q35: 0 | R35: 0 | S35: 0 | T35: 0 | U35: 0 | V35: 0 | W35: 0 | X35: 0 | Y35: 0 | Z35: 0 | AA35: 0 | AB35: 0 | AC35: 0 | AD35: 0 | AE35: 0 | AF35: 0 | AG35: 0 | AH35: 0 | AI35: 0 | AJ35: 0 | AK35: 0 | AL35: 0 | AM35: 0 | AN35: 0 | AO35: 0 | AP35: 0 | AQ35: 0 | AR35: 0 | AS35: 0 | AT35: 0 | AU35: 0 | AV35: 0 | AW35: 0 | AX35: 0 | AY35: 0 | BA35: 0 | BB35: 0 | BC35: 0 | BD35: 0 | BE35: 0 | BF35: 0 | BG35: 0 | BH35: 0 | BI35: 0 | BJ35: 0 | BK35: 0 | BL35: 0 | BM35: 0 | BN35: 0 | BO35: 0 | BP35: 0 | BQ35: 0 | BR35: 0 | BS35: 0 | BT35: 0 | BU35: 0 | BV35: 0 | BW35: 0 | BX35: 0 | BY35: 0 | BZ35: 0 | CA35: 0 | CB35: 0 | CC35: 0
A36: 마스카포네치즈 | B36: 0 | C36: 0 | D36: 0 | E36: 0 | F36: 0 | G36: 0 | H36: 0 | I36: 0 | J36: 0 | K36: 0 | L36: 0 | M36: 0 | N36: 7.14 | O36: 0 | P36: 0 | Q36: 0 | R36: 0 | S36: 0 | T36: 0 | U36: 0 | V36: 0 | W36: 0 | X36: 0 | Y36: 0 | Z36: 0 | AA36: 0 | AB36: 0 | AC36: 0 | AD36: 0 | AE36: 0 | AF36: 0 | AG36: 0 | AH36: 0 | AI36: 0 | AJ36: 0 | AK36: 0 | AL36: 0 | AM36: 0 | AN36: 0 | AO36: 0 | AP36: 0 | AQ36: 0 | AR36: 0 | AS36: 0 | AT36: 0 | AU36: 0 | AV36: 0 | AW36: 0 | AX36: 0 | AY36: 0 | BA36: 0 | BB36: 0 | BC36: 0 | BD36: 0 | BE36: 0 | BF36: 0 | BG36: 0 | BH36: 0 | BI36: 0 | BJ36: 0 | BK36: 0 | BL36: 0 | BM36: 0 | BN36: 0 | BO36: 0 | BP36: 0 | BQ36: 0 | BR36: 0 | BS36: 0 | BT36: 0 | BU36: 0 | BV36: 0 | BW36: 0 | BX36: 0 | BY36: 0 | BZ36: 0 | CA36: 0 | CB36: 0 | CC36: 0
A37: 마카다미아분태(호주산) | B37: 0 | C37: 0 | D37: 0 | E37: 0 | F37: 0 | G37: 0 | H37: 0 | I37: 0 | J37: 0 | K37: 0 | L37: 0 | M37: 0 | N37: 0 | O37: 0 | P37: 4.3 | Q37: 4.9 | R37: 4.9 | S37: 4.9 | T37: 0 | U37: 0 | V37: 0 | W37: 0 | X37: 0 | Y37: 0 | Z37: 0 | AA37: 0 | AB37: 0 | AC37: 0 | AD37: 0 | AE37: 0 | AF37: 0 | AG37: 0 | AH37: 0 | AI37: 0 | AJ37: 0 | AK37: 0 | AL37: 0 | AM37: 0 | AN37: 0 | AO37: 0 | AP37: 0 | AQ37: 0 | AR37: 0 | AS37: 0 | AT37: 0 | AU37: 0 | AV37: 0 | AW37: 0 | AX37: 0 | AY37: 0 | BA37: 0 | BB37: 0 | BC37: 0 | BD37: 0 | BE37: 0 | BF37: 0 | BG37: 0 | BH37: 0 | BI37: 0 | BJ37: 0 | BK37: 0 | BL37: 0 | BM37: 0 | BN37: 0 | BO37: 0 | BP37: 0 | BQ37: 0 | BR37: 0 | BS37: 0 | BT37: 0 | BU37: 0 | BV37: 0 | BW37: 0 | BX37: 0 | BY37: 0 | BZ37: 0 | CA37: 0 | CB37: 0 | CC37: 0
A38: 멥쌀(국내산) | B38: 0 | C38: 0 | D38: 67.3 | E38: 0 | F38: 61.7 | G38: 0 | H38: 0 | I38: 68.1 | J38: 0 | K38: 0 | L38: 0 | M38: 0 | N38: 0 | O38: 0 | P38: 0 | Q38: 0 | R38: 0 | S38: 0 | T38: 63.2 | U38: 0 | V38: 48.4 | W38: 0 | X38: 0 | Y38: 63.5 | Z38: 0 | AA38: 26.67 | AB38: 65.2 | AC38: 0 | AD38: 99 | AE38: 100 | AF38: 95 | AG38: 96 | AH38: 63.6 | AI38: 48.4 | AJ38: 17.7 | AK38: 63.9 | AL38: 0 | AM38: 0 | AN38: 0 | AO38: 0 | AP38: 47.73 | AQ38: 0 | AR38: 0 | AS38: 69.5 | AT38: 0 | AU38: 61.7 | AV38: 63.7 | AW38: 83.4 | AX38: 0 | AY38: 0 | AZ38: 2 | BA38: 66.2 | BB38: 61.5 | BC38: 0 | BD38: 58.2 | BE38: 0 | BF38: 0 | BG38: 0 | BH38: 0 | BI38: 0 | BJ38: 0 | BK38: 0 | BL38: 0 | BM38: 0 | BN38: 0 | BO38: 0 | BP38: 0 | BQ38: 0 | BR38: 0 | BS38: 0 | BT38: 0 | BU38: 60.7 | BV38: 0 | BW38: 0 | BX38: 67.1 | BY38: 63.4 | BZ38: 0 | CA38: 53.1 | CB38: 62.7 | CC38: 0
A39: 모시잎(국내산) | B39: 0 | C39: 0 | D39: 0 | E39: 0 | F39: 0 | G39: 0 | H39: 0 | I39: 0 | J39: 0 | K39: 0 | L39: 0 | M39: 0 | N39: 0 | O39: 0 | P39: 0 | Q39: 0 | R39: 0 | S39: 0 | T39: 0 | U39: 0 | V39: 12.1 | W39: 14.3 | X39: 0 | Y39: 0 | Z39: 0 | AA39: 6.68 | AB39: 0 | AC39: 0 | AD39: 0 | AE39: 0 | AF39: 0 | AG39: 0 | AH39: 0 | AI39: 0 | AJ39: 0 | AK39: 0 | AL39: 0 | AM39: 0 | AN39: 0 | AO39: 0 | AP39: 0 | AQ39: 0 | AR39: 0 | AS39: 0 | AT39: 0 | AU39: 0 | AV39: 0 | AW39: 0 | AX39: 0 | AY39: 0 | BA39: 0 | BB39: 0 | BC39: 0 | BD39: 0 | BE39: 0 | BF39: 0 | BG39: 0 | BH39: 0 | BI39: 0 | BJ39: 0 | BK39: 0 | BL39: 0 | BM39: 0 | BN39: 0 | BO39: 0 | BP39: 0 | BQ39: 0 | BR39: 0 | BS39: 0 | BT39: 0 | BU39: 0 | BV39: 0 | BW39: 0 | BX39: 0 | BY39: 0 | BZ39: 0 | CA39: 0 | CB39: 0 | CC39: 0
A40: 물엿(저당물엿) | B40: 2.7 | C40: 0 | D40: 0 | E40: 4.7 | F40: 0 | G40: 0 | H40: 0 | I40: 0 | J40: 5.43 | K40: 5.43 | L40: 5.43 | M40: 5.43 | N40: 5.43 | O40: 5.43 | P40: 2.1 | Q40: 0 | R40: 0 | S40: 0 | T40: 0 | U40: 0 | V40: 2 | W40: 3.6 | X40: 5.1 | Y40: 0 | Z40: 0 | AA40: 0 | AB40: 0 | AC40: 0 | AD40: 0 | AE40: 0 | AF40: 0 | AG40: 0 | AH40: 0 | AI40: 2 | AJ40: 0 | AK40: 0 | AL40: 0 | AM40: 6.8 | AN40: 4.4 | AO40: 0 | AP40: 0 | AQ40: 0 | AR40: 2.4 | AS40: 0 | AT40: 4.2 | AU40: 0 | AV40: 0 | AW40: 0 | AX40: 0 | AY40: 0 | BA40: 0 | BB40: 0 | BC40: 3.9 | BD40: 0 | BE40: 4.4 | BF40: 2 | BG40: 1.9 | BH40: 2 | BI40: 4.7 | BJ40: 1.5 | BK40: 2.2 | BL40: 3 | BM40: 2.2 | BN40: 2 | BO40: 4.77 | BP40: 4.7 | BQ40: 0 | BR40: 2.7 | BS40: 1.9 | BT40: 2 | BU40: 0 | BV40: 0 | BW40: 0 | BX40: 0 | BY40: 0 | BZ40: 7.4 | CA40: 0 | CB40: 0 | CC40: 0 | CD40: 3 | CE40: 2.8
...

Sheet 📦 일일 생산 입력
A1: 📦 일일 생산 실적 입력 — 원료 사용량 자동 계산 (500행 확장판)
A2: ⚡ 노란색 칸(날짜·제품명·생산량)을 입력하면 80개 원재료 사용량이 자동 계산됩니다. 최대 500건 입력 가능.
A3: No | B3: 생산일자 | C3: 제 품 명 | D3: 생산량 (kg) | E3: LOT번호 | F3: 작업자 | G3: 원료별 사용량 (kg) — 자동 계산 [80개 원재료] | CJ3: 원재료 원가(원) | CL3: YYYYMM
G4: 간장 | H4: 강낭콩((울타리콩)) | I4: 건조딸기다이스(외국산) | J4: 건포도 | K4: 건호박채(중국산) | L4: 검정깨(흑임자) | M4: 검정콩 | N4: 계피가루 | O4: 고구마가루 | P4: 고구마무스 | Q4: 고려엉겅퀴((곤드레)국내산) | R4: 기타가공품(복분자가루) | S4: 기타가공품(슈퍼소프트엠) | T4: 기타가공품(파인소프트 E-티) | U4: 기타가공품(프리미엄카스테라가루) | V4: 기타가공품(흑임자가루) | W4: 기타설탕(흑설탕) | X4: 냉동쑥(국내산) | Y4: 냉동증숙고구마(중국산) | Z4: 녹차가루 | AA4: 다크초콜릿 컴파운드칩 | AB4: 단호박분말(중국산) | AC4: 당류가공품(단호박농축액) | AD4: 당류가공품(알룰로스,에리스리톨,스테비올배당체혼합) | AE4: 당류가공품(알룰로스제로파우더) | AF4: 당절임(완두배기) | AG4: 대추농축액 | AH4: 대추채(국내산) | AI4: 동부(미얀마산) | AJ4: 두류가공품(백옥앙금) | AK4: 두류가공품(콩고물) | AL4: 두류가공품(통팥고물) | AM4: 딸기레진 | AN4: 딸기분말(스트로우베리에이드(분말)) | AO4: 마스카포네치즈 | AP4: 마카다미아분태(호주산) | AQ4: 멥쌀(국내산) | AR4: 모시잎(국내산) | AS4: 물엿(저당물엿) | AT4: 밤다이스 | AU4: 변성전분(타피오카전분) | AV4: 복음땅콩분태 | AW4: 사양벌꿀(국내산) | AX4: 생크림 | AY4: 서양호박(국내산,뉴질랜드산) | AZ4: 설탕 | BA4: 스트로우베리 에이드 후레쉬 | BB4: 식물성기름혼합제제(분홍) | BC4: 식물성기름혼합제제(초록) | BD4: 식물성기름혼합제제(황색) | BE4: 쑥가루(국내산) | BF4: 아몬드슬라이스 | BG4: 알룰로오스(국내산) | BH4: 연유 | BI4: 옥수수전분 | BJ4: 완두배기 | BK4: 우유(국내산) | BL4: 자색고구마가루(중국산) | BM4: 자연치즈(체다치즈) | BN4: 정제수 | BO4: 젤라틴 | BP4: 조림류(백옥앙금) | BQ4: 조림류(통팥앙금) | BR4: 준초콜릿(외국산) | BS4: 중력분 | BT4: 참깨(인도산,나이지리아산,탄자니아산,미얀마산) | BU4: 찹쌀(국내산) | BV4: 천일염 | BW4: 치즈 [크림치즈] | BX4: 코코아가공품류(코코아분말) | BY4: 콩기름(대두유) | BZ4: 해바라기씨앗 | CA4: 현미(국내산) | CB4: 현미멥쌀(국내산) | CC4: 호두분태(미국산) | CD4: 호박씨앗(외국산) | CE4: 혼합제제(떡용에스텔) | CF4: 혼합제제(스테비아) | CG4: 화이트초콜릿 | CH4: 흑미찹쌀(국내산) | CI4: 찰옥수수전분(미국산) | CL4: (보조)
A5: 1 | B5: 45940 | C5: 콩고물쑥떡 | D5: 210 | G5: =IFERROR(IF($C5="","",IF($D5="","",IFERROR(ROUND($D5*INDEX('🔖 배합비 참조'!$B$2:$CE$83,MATCH("간장",'🔖 배합비 참조'!$A$2:$A$83,0),MATCH($C5,'🔖 배합비 참조'!$B$1:$CE$1,0))/100,0),""))),"") -> 0 | H5: =IFERROR(IF($C5="","",IF($D5="","",IFERROR(ROUND($D5*INDEX('🔖 배합비 참조'!$B$2:$CE$83,MATCH("강낭콩((울타리콩))",'🔖 배합비 참조'!$A$2:$A$83,0),MATCH($C5,'🔖 배합비 참조'!$B$1:$CE$1,0))/100,0),""))),"") -> 0 | I5: =IFERROR(IF($C5="","",IF($D5="","",IFERROR(ROUND($D5*INDEX('🔖 배합비 참조'!$B$2:$CE$83,MATCH("건조딸기다이스(외국산)",'🔖 배합비 참조'!$A$2:$A$83,0),MATCH($C5,'🔖 배합비 참조'!$B$1:$CE$1,0))/100,0),""))),"") -> 0 | J5: =IFERROR(IF($C5="","",IF($D5="","",IFERROR(ROUND($D5*INDEX('🔖 배합비 참조'!$B$2:$CE$83,MATCH("건포도",'🔖 배합비 참조'!$A$2:$A$83,0),MATCH($C5,'🔖 배합비 참조'!$B$1:$CE$1,0))/100,0),""))),"") -> 0 | K5: =IFERROR(IF($C5="","",IF($D5="","",IFERROR(ROUND($D5*INDEX('🔖 배합비 참조'!$B$2:$CE$83,MATCH("건호박채(중국산)",'🔖 배합비 참조'!$A$2:$A$83,0),MATCH($C5,'🔖 배합비 참조'!$B$1:$CE$1,0))/100,0),""))),"") -> 0 | L5: =IFERROR(IF($C5="","",IF($D5="","",IFERROR(ROUND($D5*INDEX('🔖 배합비 참조'!$B$2:$CE$83,MATCH("검정깨(흑임자)",'🔖 배합비 참조'!$A$2:$A$83,0),MATCH($C5,'🔖 배합비 참조'!$B$1:$CE$1,0))/100,0),""))),"") -> 0 | M5: =IFERROR(IF($C5="","",IF($D5="","",IFERROR(ROUND($D5*INDEX('🔖 배합비 참조'!$B$2:$CE$83,MATCH("검정콩",'🔖 배합비 참조'!$A$2:$A$83,0),MATCH($C5,'🔖 배합비 참조'!$B$1:$CE$1,0))/100,0),""))),"") -> 0 | N5: =IFERROR(IF($C5="","",IF($D5="","",IFERROR(ROUND($D5*INDEX('🔖 배합비 참조'!$B$2:$CE$83,MATCH("계피가루",'🔖 배합비 참조'!$A$2:$A$83,0),MATCH($C5,'🔖 배합비 참조'!$B$1:$CE$1,0))/100,0),""))),"") -> 0 | O5: =IFERROR(IF($C5="","",IF($D5="","",IFERROR(ROUND($D5*INDEX('🔖 배합비 참조'!$B$2:$CE$83,MATCH("고구마가루",'🔖 배합비 참조'!$A$2:$A$83,0),MATCH($C5,'🔖 배합비 참조'!$B$1:$CE$1,0))/100,0),""))),"") -> 0 | P5: =IFERROR(IF($C5="","",IF($D5="","",IFERROR(ROUND($D5*INDEX('🔖 배합비 참조'!$B$2:$CE$83,MATCH("고구마무스",'🔖 배합비 참조'!$A$2:$A$83,0),MATCH($C5,'🔖 배합비 참조'!$B$1:$CE$1,0))/100,0),""))),"") -> 0 | Q5: =IFERROR(IF($C5="","",IF($D5="","",IFERROR(ROUND($D5*INDEX('🔖 배합비 참조'!$B$2:$CE$83,MATCH("고려엉겅퀴((곤드레)국내산)",'🔖 배합비 참조'!$A$2:$A$83,0),MATCH($C5,'🔖 배합비 참조'!$B$1:$CE$1,0))/100,0),""))),"") -> 0 | R5: =IFERROR(IF($C5="","",IF($D5="","",IFERROR(ROUND($D5*INDEX('🔖 배합비 참조'!$B$2:$CE$83,MATCH("기타가공품(복분자가루)",'🔖 배합비 참조'!$A$2:$A$83,0),MATCH($C5,'🔖 배합비 참조'!$B$1:$CE$1,0))/100,0),""))),"") -> 0 | S5: =IFERROR(IF($C5="","",IF($D5="","",IFERROR(ROUND($D5*INDEX('🔖 배합비 참조'!$B$2:$CE$83,MATCH("기타가공품(슈퍼소프트엠)",'🔖 배합비 참조'!$A$2:$A$83,0),MATCH($C5,'🔖 배합비 참조'!$B$1:$CE$1,0))/100,0),""))),"") -> 0 | T5: =IFERROR(IF($C5="","",IF($D5="","",IFERROR(ROUND($D5*INDEX('🔖 배합비 참조'!$B$2:$CE$83,MATCH("기타가공품(파인소프트 E-티)",'🔖 배합비 참조'!$A$2:$A$83,0),MATCH($C5,'🔖 배합비 참조'!$B$1:$CE$1,0))/100,0),""))),"") -> 0 | U5: =IFERROR(IF($C5="","",IF($D5="","",IFERROR(ROUND($D5*INDEX('🔖 배합비 참조'!$B$2:$CE$83,MATCH("기타가공품(프리미엄카스테라가루)",'🔖 배합비 참조'!$A$2:$A$83,0),MATCH($C5,'🔖 배합비 참조'!$B$1:$CE$1,0))/100,0),""))),"") -> 0 | V5: =IFERROR(IF($C5="","",IF($D5="","",IFERROR(ROUND($D5*INDEX('🔖 배합비 참조'!$B$2:$CE$83,MATCH("기타가공품(흑임자가루)",'🔖 배합비 참조'!$A$2:$A$83,0),MATCH($C5,'🔖 배합비 참조'!$B$1:$CE$1,0))/100,0),""))),"") -> 0 | W5: =IFERROR(IF($C5="","",IF($D5="","",IFERROR(ROUND($D5*INDEX('🔖 배합비 참조'!$B$2:$CE$83,MATCH("기타설탕(흑설탕)",'🔖 배합비 참조'!$A$2:$A$83,0),MATCH($C5,'🔖 배합비 참조'!$B$1:$CE$1,0))/100,0),""))),"") -> 0 | X5: =IFERROR(IF($C5="","",IF($D5="","",IFERROR(ROUND($D5*INDEX('🔖 배합비 참조'!$B$2:$CE$83,MATCH("냉동쑥(국내산)",'🔖 배합비 참조'!$A$2:$A$83,0),MATCH($C5,'🔖 배합비 참조'!$B$1:$CE$1,0))/100,0),""))),"") -> 7 | Y5: =IFERROR(IF($C5="","",IF($D5="","",IFERROR(ROUND($D5*INDEX('🔖 배합비 참조'!$B$2:$CE$83,MATCH("냉동증숙고구마(중국산)",'🔖 배합비 참조'!$A$2:$A$83,0),MATCH($C5,'🔖 배합비 참조'!$B$1:$CE$1,0))/100,0),""))),"") -> 0 | Z5: =IFERROR(IF($C5="","",IF($D5="","",IFERROR(ROUND($D5*INDEX('🔖 배합비 참조'!$B$2:$CE$83,MATCH("녹차가루",'🔖 배합비 참조'!$A$2:$A$83,0),MATCH($C5,'🔖 배합비 참조'!$B$1:$CE$1,0))/100,0),""))),"") -> 0 | AA5: =IFERROR(IF($C5="","",IF($D5="","",IFERROR(ROUND($D5*INDEX('🔖 배합비 참조'!$B$2:$CE$83,MATCH("다크초콜릿 컴파운드칩",'🔖 배합비 참조'!$A$2:$A$83,0),MATCH($C5,'🔖 배합비 참조'!$B$1:$CE$1,0))/100,0),""))),"") -> 0 | AB5: =IFERROR(IF($C5="","",IF($D5="","",IFERROR(ROUND($D5*INDEX('🔖 배합비 참조'!$B$2:$CE$83,MATCH("단호박분말(중국산)",'🔖 배합비 참조'!$A$2:$A$83,0),MATCH($C5,'🔖 배합비 참조'!$B$1:$CE$1,0))/100,0),""))),"") -> 0 | AC5: =IFERROR(IF($C5="","",IF($D5="","",IFERROR(ROUND($D5*INDEX('🔖 배합비 참조'!$B$2:$CE$83,MATCH("당류가공품(단호박농축액)",'🔖 배합비 참조'!$A$2:$A$83,0),MATCH($C5,'🔖 배합비 참조'!$B$1:$CE$1,0))/100,0),""))),"") -> 0 | AD5: =IFERROR(IF($C5="","",IF($D5="","",IFERROR(ROUND($D5*INDEX('🔖 배합비 참조'!$B$2:$CE$83,MATCH("당류가공품(알룰로스,에리스리톨,스테비올배당체혼합)",'🔖 배합비 참조'!$A$2:$A$83,0),MATCH($C5,'🔖 배합비 참조'!$B$1:$CE$1,0))/100,0),""))),"") -> 0 | AE5: =IFERROR(IF($C5="","",IF($D5="","",IFERROR(ROUND($D5*INDEX('🔖 배합비 참조'!$B$2:$CE$83,MATCH("당류가공품(알룰로스제로파우더)",'🔖 배합비 참조'!$A$2:$A$83,0),MATCH($C5,'🔖 배합비 참조'!$B$1:$CE$1,0))/100,0),""))),"") -> 0 | AF5: =IFERROR(IF($C5="","",IF($D5="","",IFERROR(ROUND($D5*INDEX('🔖 배합비 참조'!$B$2:$CE$83,MATCH("당절임(완두배기)",'🔖 배합비 참조'!$A$2:$A$83,0),MATCH($C5,'🔖 배합비 참조'!$B$1:$CE$1,0))/100,0),""))),"") -> 0 | AG5: =IFERROR(IF($C5="","",IF($D5="","",IFERROR(ROUND($D5*INDEX('🔖 배합비 참조'!$B$2:$CE$83,MATCH("대추농축액",'🔖 배합비 참조'!$A$2:$A$83,0),MATCH($C5,'🔖 배합비 참조'!$B$1:$CE$1,0))/100,0),""))),"") -> 0 | AH5: =IFERROR(IF($C5="","",IF($D5="","",IFERROR(ROUND($D5*INDEX('🔖 배합비 참조'!$B$2:$CE$83,MATCH("대추채(국내산)",'🔖 배합비 참조'!$A$2:$A$83,0),MATCH($C5,'🔖 배합비 참조'!$B$1:$CE$1,0))/100,0),""))),"") -> 0 | AI5: =IFERROR(IF($C5="","",IF($D5="","",IFERROR(ROUND($D5*INDEX('🔖 배합비 참조'!$B$2:$CE$83,MATCH("동부(미얀마산)",'🔖 배합비 참조'!$A$2:$A$83,0),MATCH($C5,'🔖 배합비 참조'!$B$1:$CE$1,0))/100,0),""))),"") -> 0 | AJ5: =IFERROR(IF($C5="","",IF($D5="","",IFERROR(ROUND($D5*INDEX('🔖 배합비 참조'!$B$2:$CE$83,MATCH("두류가공품(백옥앙금)",'🔖 배합비 참조'!$A$2:$A$83,0),MATCH($C5,'🔖 배합비 참조'!$B$1:$CE$1,0))/100,0),""))),"") -> 0 | AK5: =IFERROR(IF($C5="","",IF($D5="","",IFERROR(ROUND($D5*INDEX('🔖 배합비 참조'!$B$2:$CE$83,MATCH("두류가공품(콩고물)",'🔖 배합비 참조'!$A$2:$A$83,0),MATCH($C5,'🔖 배합비 참조'!$B$1:$CE$1,0))/100,0),""))),"") -> 6 | AL5: =IFERROR(IF($C5="","",IF($D5="","",IFERROR(ROUND($D5*INDEX('🔖 배합비 참조'!$B$2:$CE$83,MATCH("두류가공품(통팥고물)",'🔖 배합비 참조'!$A$2:$A$83,0),MATCH($C5,'🔖 배합비 참조'!$B$1:$CE$1,0))/100,0),""))),"") -> 0 | AM5: =IFERROR(IF($C5="","",IF($D5="","",IFERROR(ROUND($D5*INDEX('🔖 배합비 참조'!$B$2:$CE$83,MATCH("딸기레진",'🔖 배합비 참조'!$A$2:$A$83,0),MATCH($C5,'🔖 배합비 참조'!$B$1:$CE$1,0))/100,0),""))),"") -> 0 | AN5: =IFERROR(IF($C5="","",IF($D5="","",IFERROR(ROUND($D5*INDEX('🔖 배합비 참조'!$B$2:$CE$83,MATCH("딸기분말(스트로우베리에이드(분말))",'🔖 배합비 참조'!$A$2:$A$83,0),MATCH($C5,'🔖 배합비 참조'!$B$1:$CE$1,0))/100,0),""))),"") -> 0 | AO5: =IFERROR(IF($C5="","",IF($D5="","",IFERROR(ROUND($D5*INDEX('🔖 배합비 참조'!$B$2:$CE$83,MATCH("마스카포네치즈",'🔖 배합비 참조'!$A$2:$A$83,0),MATCH($C5,'🔖 배합비 참조'!$B$1:$CE$1,0))/100,0),""))),"") -> 0 | AP5: =IFERROR(IF($C5="","",IF($D5="","",IFERROR(ROUND($D5*INDEX('🔖 배합비 참조'!$B$2:$CE$83,MATCH("마카다미아분태(호주산)",'🔖 배합비 참조'!$A$2:$A$83,0),MATCH($C5,'🔖 배합비 참조'!$B$1:$CE$1,0))/100,0),""))),"") -> 0 | AQ5: =IFERROR(IF($C5="","",IF($D5="","",IFERROR(ROUND($D5*INDEX('🔖 배합비 참조'!$B$2:$CE$83,MATCH("멥쌀(국내산)",'🔖 배합비 참조'!$A$2:$A$83,0),MATCH($C5,'🔖 배합비 참조'!$B$1:$CE$1,0))/100,0),""))),"") -> 0 | AR5: =IFERROR(IF($C5="","",IF($D5="","",IFERROR(ROUND($D5*INDEX('🔖 배합비 참조'!$B$2:$CE$83,MATCH("모시잎(국내산)",'🔖 배합비 참조'!$A$2:$A$83,0),MATCH($C5,'🔖 배합비 참조'!$B$1:$CE$1,0))/100,0),""))),"") -> 0 | AS5: =IFERROR(IF($C5="","",IF($D5="","",IFERROR(ROUND($D5*INDEX('🔖 배합비 참조'!$B$2:$CE$83,MATCH("물엿(저당물엿)",'🔖 배합비 참조'!$A$2:$A$83,0),MATCH($C5,'🔖 배합비 참조'!$B$1:$CE$1,0))/100,0),""))),"") -> 5 | AT5: =IFERROR(IF($C5="","",IF($D5="","",IFERROR(ROUND($D5*INDEX('🔖 배합비 참조'!$B$2:$CE$83,MATCH("밤다이스",'🔖 배합비 참조'!$A$2:$A$83,0),MATCH($C5,'🔖 배합비 참조'!$B$1:$CE$1,0))/100,0),""))),"") -> 0 | AU5: =IFERROR(IF($C5="","",IF($D5="","",IFERROR(ROUND($D5*INDEX('🔖 배합비 참조'!$B$2:$CE$83,MATCH("변성전분(타피오카전분)",'🔖 배합비 참조'!$A$2:$A$83,0),MATCH($C5,'🔖 배합비 참조'!$B$1:$CE$1,0))/100,0),""))),"") -> 0 | AV5: =IFERROR(IF($C5="","",IF($D5="","",IFERROR(ROUND($D5*INDEX('🔖 배합비 참조'!$B$2:$CE$83,MATCH("복음땅콩분태",'🔖 배합비 참조'!$A$2:$A$83,0),MATCH($C5,'🔖 배합비 참조'!$B$1:$CE$1,0))/100,0),""))),"") -> 0 | AW5: =IFERROR(IF($C5="","",IF($D5="","",IFERROR(ROUND($D5*INDEX('🔖 배합비 참조'!$B$2:$CE$83,MATCH("사양벌꿀(국내산)",'🔖 배합비 참조'!$A$2:$A$83,0),MATCH($C5,'🔖 배합비 참조'!$B$1:$CE$1,0))/100,0),""))),"") -> 0 | AX5: =IFERROR(IF($C5="","",IF($D5="","",IFERROR(ROUND($D5*INDEX('🔖 배합비 참조'!$B$2:$CE$83,MATCH("생크림",'🔖 배합비 참조'!$A$2:$A$83,0),MATCH($C5,'🔖 배합비 참조'!$B$1:$CE$1,0))/100,0),""))),"") -> 0 | AY5: =IFERROR(IF($C5="","",IF($D5="","",IFERROR(ROUND($D5*INDEX('🔖 배합비 참조'!$B$2:$CE$83,MATCH("서양호박(국내산,뉴질랜드산)",'🔖 배합비 참조'!$A$2:$A$83,0),MATCH($C5,'🔖 배합비 참조'!$B$1:$CE$1,0))/100,0),""))),"") -> 0 | AZ5: =IFERROR(IF($C5="","",IF($D5="","",IFERROR(ROUND($D5*INDEX('🔖 배합비 참조'!$B$2:$CE$83,MATCH("설탕",'🔖 배합비 참조'!$A$2:$A$83,0),MATCH($C5,'🔖 배합비 참조'!$B$1:$CE$1,0))/100,0),""))),"") -> 5 | BA5: =IFERROR(IF($C5="","",IF($D5="","",IFERROR(ROUND($D5*INDEX('🔖 배합비 참조'!$B$2:$CE$83,MATCH("스트로우베리 에이드 후레쉬",'🔖 배합비 참조'!$A$2:$A$83,0),MATCH($C5,'🔖 배합비 참조'!$B$1:$CE$1,0))/100,0),""))),"") -> 0 | BB5: =IFERROR(IF($C5="","",IF($D5="","",IFERROR(ROUND($D5*INDEX('🔖 배합비 참조'!$B$2:$CE$83,MATCH("식물성기름혼합제제(분홍)",'🔖 배합비 참조'!$A$2:$A$83,0),MATCH($C5,'🔖 배합비 참조'!$B$1:$CE$1,0))/100,0),""))),"") -> 0 | BC5: =IFERROR(IF($C5="","",IF($D5="","",IFERROR(ROUND($D5*INDEX('🔖 배합비 참조'!$B$2:$CE$83,MATCH("식물성기름혼합제제(초록)",'🔖 배합비 참조'!$A$2:$A$83,0),MATCH($C5,'🔖 배합비 참조'!$B$1:$CE$1,0))/100,0),""))),"") -> 0 | BD5: =IFERROR(IF($C5="","",IF($D5="","",IFERROR(ROUND($D5*INDEX('🔖 배합비 참조'!$B$2:$CE$83,MATCH("식물성기름혼합제제(황색)",'🔖 배합비 참조'!$A$2:$A$83,0),MATCH($C5,'🔖 배합비 참조'!$B$1:$CE$1,0))/100,0),""))),"") -> 0 | BE5: =IFERROR(IF($C5="","",IF($D5="","",IFERROR(ROUND($D5*INDEX('🔖 배합비 참조'!$B$2:$CE$83,MATCH("쑥가루(국내산)",'🔖 배합비 참조'!$A$2:$A$83,0),MATCH($C5,'🔖 배합비 참조'!$B$1:$CE$1,0))/100,0),""))),"") -> 2 | BF5: =IFERROR(IF($C5="","",IF($D5="","",IFERROR(ROUND($D5*INDEX('🔖 배합비 참조'!$B$2:$CE$83,MATCH("아몬드슬라이스",'🔖 배합비 참조'!$A$2:$A$83,0),MATCH($C5,'🔖 배합비 참조'!$B$1:$CE$1,0))/100,0),""))),"") -> 0 | BG5: =IFERROR(IF($C5="","",IF($D5="","",IFERROR(ROUND($D5*INDEX('🔖 배합비 참조'!$B$2:$CE$83,MATCH("알룰로오스(국내산)",'🔖 배합비 참조'!$A$2:$A$83,0),MATCH($C5,'🔖 배합비 참조'!$B$1:$CE$1,0))/100,0),""))),"") -> 0 | BH5: =IFERROR(IF($C5="","",IF($D5="","",IFERROR(ROUND($D5*INDEX('🔖 배합비 참조'!$B$2:$CE$83,MATCH("연유",'🔖 배합비 참조'!$A$2:$A$83,0),MATCH($C5,'🔖 배합비 참조'!$B$1:$CE$1,0))/100,0),""))),"") -> 0 | BI5: =IFERROR(IF($C5="","",IF($D5="","",IFERROR(ROUND($D5*INDEX('🔖 배합비 참조'!$B$2:$CE$83,MATCH("옥수수전분",'🔖 배합비 참조'!$A$2:$A$83,0),MATCH($C5,'🔖 배합비 참조'!$B$1:$CE$1,0))/100,0),""))),"") -> 0 | BJ5: =IFERROR(IF($C5="","",IF($D5="","",IFERROR(ROUND($D5*INDEX('🔖 배합비 참조'!$B$2:$CE$83,MATCH("완두배기",'🔖 배합비 참조'!$A$2:$A$83,0),MATCH($C5,'🔖 배합비 참조'!$B$1:$CE$1,0))/100,0),""))),"") -> 0 | BK5: =IFERROR(IF($C5="","",IF($D5="","",IFERROR(ROUND($D5*INDEX('🔖 배합비 참조'!$B$2:$CE$83,MATCH("우유(국내산)",'🔖 배합비 참조'!$A$2:$A$83,0),MATCH($C5,'🔖 배합비 참조'!$B$1:$CE$1,0))/100,0),""))),"") -> 0 | BL5: =IFERROR(IF($C5="","",IF($D5="","",IFERROR(ROUND($D5*INDEX('🔖 배합비 참조'!$B$2:$CE$83,MATCH("자색고구마가루(중국산)",'🔖 배합비 참조'!$A$2:$A$83,0),MATCH($C5,'🔖 배합비 참조'!$B$1:$CE$1,0))/100,0),""))),"") -> 0 | BM5: =IFERROR(IF($C5="","",IF($D5="","",IFERROR(ROUND($D5*INDEX('🔖 배합비 참조'!$B$2:$CE$83,MATCH("자연치즈(체다치즈)",'🔖 배합비 참조'!$A$2:$A$83,0),MATCH($C5,'🔖 배합비 참조'!$B$1:$CE$1,0))/100,0),""))),"") -> 0 | BN5: =IFERROR(IF($C5="","",IF($D5="","",IFERROR(ROUND($D5*INDEX('🔖 배합비 참조'!$B$2:$CE$83,MATCH("정제수",'🔖 배합비 참조'!$A$2:$A$83,0),MATCH($C5,'🔖 배합비 참조'!$B$1:$CE$1,0))/100,0),""))),"") -> 0 | BO5: =IFERROR(IF($C5="","",IF($D5="","",IFERROR(ROUND($D5*INDEX('🔖 배합비 참조'!$B$2:$CE$83,MATCH("젤라틴",'🔖 배합비 참조'!$A$2:$A$83,0),MATCH($C5,'🔖 배합비 참조'!$B$1:$CE$1,0))/100,0),""))),"") -> 0 | BP5: =IFERROR(IF($C5="","",IF($D5="","",IFERROR(ROUND($D5*INDEX('🔖 배합비 참조'!$B$2:$CE$83,MATCH("조림류(백옥앙금)",'🔖 배합비 참조'!$A$2:$A$83,0),MATCH($C5,'🔖 배합비 참조'!$B$1:$CE$1,0))/100,0),""))),"") -> 0 | BQ5: =IFERROR(IF($C5="","",IF($D5="","",IFERROR(ROUND($D5*INDEX('🔖 배합비 참조'!$B$2:$CE$83,MATCH("조림류(통팥앙금)",'🔖 배합비 참조'!$A$2:$A$83,0),MATCH($C5,'🔖 배합비 참조'!$B$1:$CE$1,0))/100,0),""))),"") -> 87 | BR5: =IFERROR(IF($C5="","",IF($D5="","",IFERROR(ROUND($D5*INDEX('🔖 배합비 참조'!$B$2:$CE$83,MATCH("준초콜릿(외국산)",'🔖 배합비 참조'!$A$2:$A$83,0),MATCH($C5,'🔖 배합비 참조'!$B$1:$CE$1,0))/100,0),""))),"") -> 0 | BS5: =IFERROR(IF($C5="","",IF($D5="","",IFERROR(ROUND($D5*INDEX('🔖 배합비 참조'!$B$2:$CE$83,MATCH("중력분",'🔖 배합비 참조'!$A$2:$A$83,0),MATCH($C5,'🔖 배합비 참조'!$B$1:$CE$1,0))/100,0),""))),"") -> 2 | BT5: =IFERROR(IF($C5="","",IF($D5="","",IFERROR(ROUND($D5*INDEX('🔖 배합비 참조'!$B$2:$CE$83,MATCH("참깨(인도산,나이지리아산,탄자니아산,미얀마산)",'🔖 배합비 참조'!$A$2:$A$83,0),MATCH($C5,'🔖 배합비 참조'!$B$1:$CE$1,0))/100,0),""))),"") -> 0 | BU5: =IFERROR(IF($C5="","",IF($D5="","",IFERROR(ROUND($D5*INDEX('🔖 배합비 참조'!$B$2:$CE$83,MATCH("찹쌀(국내산)",'🔖 배합비 참조'!$A$2:$A$83,0),MATCH($C5,'🔖 배합비 참조'!$B$1:$CE$1,0))/100,0),""))),"") -> 93 | BV5: =IFERROR(IF($C5="","",IF($D5="","",IFERROR(ROUND($D5*INDEX('🔖 배합비 참조'!$B$2:$CE$83,MATCH("천일염",'🔖 배합비 참조'!$A$2:$A$83,0),MATCH($C5,'🔖 배합비 참조'!$B$1:$CE$1,0))/100,0),""))),"") -> 2 | BW5: =IFERROR(IF($C5="","",IF($D5="","",IFERROR(ROUND($D5*INDEX('🔖 배합비 참조'!$B$2:$CE$83,MATCH("치즈 [크림치즈]",'🔖 배합비 참조'!$A$2:$A$83,0),MATCH($C5,'🔖 배합비 참조'!$B$1:$CE$1,0))/100,0),""))),"") -> 0 | BX5: =IFERROR(IF($C5="","",IF($D5="","",IFERROR(ROUND($D5*INDEX('🔖 배합비 참조'!$B$2:$CE$83,MATCH("코코아가공품류(코코아분말)",'🔖 배합비 참조'!$A$2:$A$83,0),MATCH($C5,'🔖 배합비 참조'!$B$1:$CE$1,0))/100,0),""))),"") -> 0 | BY5: =IFERROR(IF($C5="","",IF($D5="","",IFERROR(ROUND($D5*INDEX('🔖 배합비 참조'!$B$2:$CE$83,MATCH("콩기름(대두유)",'🔖 배합비 참조'!$A$2:$A$83,0),MATCH($C5,'🔖 배합비 참조'!$B$1:$CE$1,0))/100,0),""))),"") -> 0 | BZ5: =IFERROR(IF($C5="","",IF($D5="","",IFERROR(ROUND($D5*INDEX('🔖 배합비 참조'!$B$2:$CE$83,MATCH("해바라기씨앗",'🔖 배합비 참조'!$A$2:$A$83,0),MATCH($C5,'🔖 배합비 참조'!$B$1:$CE$1,0))/100,0),""))),"") -> 0 | CA5: =IFERROR(IF($C5="","",IF($D5="","",IFERROR(ROUND($D5*INDEX('🔖 배합비 참조'!$B$2:$CE$83,MATCH("현미(국내산)",'🔖 배합비 참조'!$A$2:$A$83,0),MATCH($C5,'🔖 배합비 참조'!$B$1:$CE$1,0))/100,0),""))),"") -> 0 | CB5: =IFERROR(IF($C5="","",IF($D5="","",IFERROR(ROUND($D5*INDEX('🔖 배합비 참조'!$B$2:$CE$83,MATCH("현미멥쌀(국내산)",'🔖 배합비 참조'!$A$2:$A$83,0),MATCH($C5,'🔖 배합비 참조'!$B$1:$CE$1,0))/100,0),""))),"") -> 0 | CC5: =IFERROR(IF($C5="","",IF($D5="","",IFERROR(ROUND($D5*INDEX('🔖 배합비 참조'!$B$2:$CE$83,MATCH("호두분태(미국산)",'🔖 배합비 참조'!$A$2:$A$83,0),MATCH($C5,'🔖 배합비 참조'!$B$1:$CE$1,0))/100,0),""))),"") -> 0 | CD5: =IFERROR(IF($C5="","",IF($D5="","",IFERROR(ROUND($D5*INDEX('🔖 배합비 참조'!$B$2:$CE$83,MATCH("호박씨앗(외국산)",'🔖 배합비 참조'!$A$2:$A$83,0),MATCH($C5,'🔖 배합비 참조'!$B$1:$CE$1,0))/100,0),""))),"") -> 0 | CE5: =IFERROR(IF($C5="","",IF($D5="","",IFERROR(ROUND($D5*INDEX('🔖 배합비 참조'!$B$2:$CE$83,MATCH("혼합제제(떡용에스텔)",'🔖 배합비 참조'!$A$2:$A$83,0),MATCH($C5,'🔖 배합비 참조'!$B$1:$CE$1,0))/100,0),""))),"") -> 1 | CF5: =IFERROR(IF($C5="","",IF($D5="","",IFERROR(ROUND($D5*INDEX('🔖 배합비 참조'!$B$2:$CE$83,MATCH("혼합제제(스테비아)",'🔖 배합비 참조'!$A$2:$A$83,0),MATCH($C5,'🔖 배합비 참조'!$B$1:$CE$1,0))/100,0),""))),"") -> 0 | CG5: =IFERROR(IF($C5="","",IF($D5="","",IFERROR(ROUND($D5*INDEX('🔖 배합비 참조'!$B$2:$CE$83,MATCH("화이트초콜릿",'🔖 배합비 참조'!$A$2:$A$83,0),MATCH($C5,'🔖 배합비 참조'!$B$1:$CE$1,0))/100,0),""))),"") -> 0 | CH5: =IFERROR(IF($C5="","",IF($D5="","",IFERROR(ROUND($D5*INDEX('🔖 배합비 참조'!$B$2:$CE$83,MATCH("흑미찹쌀(국내산)",'🔖 배합비 참조'!$A$2:$A$83,0),MATCH($C5,'🔖 배합비 참조'!$B$1:$CE$1,0))/100,0),""))),"") -> 0 | CI5: =IFERROR(IF($C5="","",IF($D5="","",IFERROR(ROUND($D5*INDEX('🔖 배합비 참조'!$B$2:$CE$83,MATCH("찰옥수수전분(미국산)",'🔖 배합비 참조'!$A$2:$A$83,0),MATCH($C5,'🔖 배합비 참조'!$B$1:$CE$1,0))/100,0),""))),"") -> 0 | CL5: 2025-10
